Workbook

Sheet Business Index
A1: Business Scenario | B1: Test Case ID | C1: Test Case | D1: Category | E1: Source File
A2: TS-RS-001 | B2: TC-RS-DATA-001 | C2: Cấu hình lưu và mở lại đầy đủ, không cắt/làm tròn âm thầm | D2: G. Data • Persistence | E2: test-cases.vi.md
A3: TS-RS-001 | B3: TC-RS-DATA-004 | C3: Xóa quy tắc không xóa dây chuyền kết quả hay điểm | D3: G. Data • Persistence | E3: test-cases.vi.md
A4: TS-RS-001 | B4: TC-RS-FUNC-001 | C4: Hàng Thiết lập điểm đỏ（赤点設定） xuất hiện trong Thiết lập ô nhập（入力欄設定） cho mục điểm số | D4: A. Functional | E4: test-cases.vi.md
A5: TS-RS-001 | B5: TC-RS-FUNC-002 | C5: Mục kiểu lựa chọn và Đạt/không đạt（合否） không có thao tác tạo quy tắc đỏ có hiệu lực | D5: A. Functional | E5: test-cases.vi.md
A6: TS-RS-001 | B6: TC-RS-FUNC-003 | C6: Danh sách trống không tự dựng rule từ cấu hình legacy | D6: A. Functional | E6: test-cases.vi.md
A7: TS-RS-001 | B7: TC-RS-FUNC-004 | C7: Thêm quy tắc qua Điều kiện áp dụng（適用条件） và Ngưỡng（基準設定） rồi quay lại danh sách | D7: A. Functional | E7: test-cases.vi.md
A8: TS-RS-001 | B8: TC-RS-FUNC-005 | C8: Nhiều quy tắc hiển thị theo ưu tiên; đổi thứ tự bằng ▲▼ được lưu | D8: A. Functional | E8: test-cases.vi.md
A9: TS-RS-001 | B9: TC-RS-FUNC-006 | C9: Xóa một quy tắc có xác nhận; Hủy（キャンセル） giữ nguyên | D9: A. Functional | E9: test-cases.vi.md
A10: TS-RS-001 | B10: TC-RS-FUNC-007 | C10: Quay lại（戻る）/hủy chỉnh sửa không lưu dữ liệu đang nhập | D10: A. Functional | E10: test-cases.vi.md
A11: TS-RS-001 | B11: TC-RS-FUNC-014 | C11: Quy tắc mới chỉ có điều kiện, chưa có ngưỡng, không tham gia xét | D11: A. Functional | E11: test-cases.vi.md
A12: TS-RS-001 | B12: TC-RS-FUNC-033 | C12: Đổi tên quy tắc: giữ liên kết, thứ tự và kết quả | D12: A. Functional | E12: test-cases.vi.md
... A231: TS-RS-019 | B231: TC-RS-FUNC-032 | C231: Ba đầu ra dùng cùng kết quả cho cùng ô | D231: A. Functional | E231: test-cases.vi.md

Sheet Run
A1: Run metadata | B1: Giá trị
A2: Feature | B2: RC-001 Red Score v2
A3: Scope | B3: 216 case IDs, including six restored legacy cases; Run Log expands variants into run rows
A4: Test suite revision | B4: v2 working tree based on ffa72dc90f27fd128d62c5c092a5d3e8447a466a; exact source hashes in manifest; pinned link pending commit
A5: Build | B5: Điền khi thực thi
A6: Environment | B6: Điền khi thực thi
A7: Tester | B7: Điền khi thực thi
A8: Run start | B8: Điền khi thực thi
A9: Run end | B9: Điền khi thực thi
A12: Summary
A13: Metric | B13: Value
A14: Case IDs | B14: =COUNTIF(Cases!A:A,"TC-RS-*")
A15: PASS variants | B15: =COUNTIF('Run Log'!D:D,"PASS")
A16: FAIL variants | B16: =COUNTIF('Run Log'!D:D,"FAIL")
A17: BLOCKED variants | B17: =COUNTIF('Run Log'!D:D,"BLOCKED")
A18: NOT RUN run rows | B18: =COUNTIF('Run Log'!D:D,"NOT RUN")
A19: SKIPPED variants | B19: =COUNTIF('Run Log'!D:D,"SKIPPED")
A20: Total run rows | B20: =COUNTA('Run Log'!A:A)-1
A21: Attempted variants | B21: =COUNTIF('Run Log'!D:D,"PASS")+COUNTIF('Run Log'!D:D,"FAIL")+COUNTIF('Run Log'!D:D,"BLOCKED")+COUNTIF('Run Log'!D:D,"SKIPPED")
A22: Completed cases (all required variants PASS) | B22: =COUNTIF(Cases!P:P,"PASS")
A23: Cases with incomplete variant coverage | B23: =COUNTIF(Cases!P:P,"INCOMPLETE")

Sheet Cases
A1: Test Case ID | B1: Title | C1: Function | D1: Context | E1: Priority | F1: Status | G1: Readiness | H1: Requirement ID | I1: Category | J1: Source File | K1: Action | L1: Expected | M1: Evidence | N1: Reset | O1: Required Variant Count | P1: Case Status
A2: TC-RS-FUNC-001 | B2: Hàng Thiết lập điểm đỏ（赤点設定） xuất hiện trong Thiết lập ô nhập（入力欄設定） cho mục điểm số | C2: A. Functional | D2: - Điều kiện: Đăng nhập tài khoản giáo viên có quyền sửa mục. Chưa có quy tắc đỏ cho mục số nguyên (M=100); mục số thập phân (M=100) có ít nhất một quy tắc. - Dữ liệu test: môi trường test (trường A, năm học 2026), tài khoản giáo viên có quyền sửa mục, mục số nguyên (M=100), mục số thập phân (M=100), mục điểm đơn vị (đơn vị U1 có M riêng 40) | E2: TBD | F2: PROPOSED | G2: UNASSESSED | H2: đặc tả v2 mục 4.1 “Điểm vào và trạng thái trống”; AC-G02 chỉ xác nhận loại điểm được hỗ trợ | I2: A. Functional | J2: test-cases.vi.md | K2: 1. Mở Thiết lập nhập điểm（成績入力設定）→ Thiết lập ô nhập（入力欄設定） của kỳ 1学期期末 (cuối kỳ học kỳ 1). 2. Tìm hàng Thiết lập điểm đỏ（赤点設定） ở bảng mục nhập. 3. Bấm link của hàng này ở cột mục số nguyên (M=100), mục số thập phân (M=100), mục điểm đơn vị (đơn vị U1 có M riêng 40). | Lượt chạy | Phạm vi thực hiện và đối chiếu | | --- | --- | | Run: integer | Mục số nguyên | | Run: decimal | Mục thập phân | | Run: unit | Mục đơn vị | | L2: 1. Theo Figma MW, hàng Thiết lập điểm đỏ（赤点設定） được đặt giữa hàng Tính tự động（自動計算） và hàng Thiết lập ẩn mục nhập（入力項目の非表示設定）. Đây là oracle UI PROPOSED; nếu bố cục khác, ghi Notes để đối chiếu, không mở bug từ riêng vị trí. 2. Có thao tác mở thiết lập cho mục số nguyên, số thập phân và điểm đơn vị. 3. Bấm link chuyển sang màn danh sách Thiết lập điểm đỏ（赤点設定） của đúng mục. | O2: 3 | P2: =IF(OR(COUNTIF('Run Log'!$B:$B,A2)<>O2,COUNTIF('Run Log'!$A:$A,"RUN-TC-RS-FUNC-001-integer")<>1,COUNTIFS('Run Log'!$A:$A,"RUN-TC-RS-FUNC-001-integer",'Run Log'!$B:$B,A2,'Run Log'!$C:$C,"integer")<>1,COUNTIF('Run Log'!$A:$A,"RUN-TC-RS-FUNC-001-decimal")<>1,COUNTIFS('Run Log'!$A:$A,"RUN-TC-RS-FUNC-001-decimal",'Run Log'!$B:$B,A2,'Run Log'!$C:$C,"decimal")<>1,COUNTIF('Run Log'!$A:$A,"RUN-TC-RS-FUNC-001-unit")<>1,COUNTIFS('Run Log'!$A:$A,"RUN-TC-RS-FUNC-001-unit",'Run Log'!$B:$B,A2,'Run Log'!$C:$C,"unit")<>1),"INCOMPLETE",IF(COUNTIFS('Run Log'!$B:$B,A2,'Run Log'!$D:$D,"PASS")=O2,"PASS",IF(COUNTIFS('Run Log'!$B:$B,A2,'Run Log'!$D:$D,"FAIL")>0,"FAIL",IF(COUNTIFS('Run Log'!$B:$B,A2,'Run Log'!$D:$D,"BLOCKED")>0,"BLOCKED",IF(COUNTIFS('Run Log'!$B:$B,A2,'Run Log'!$D:$D,"SKIPPED")>0,"SKIPPED","NOT RUN")))))
A3: TC-RS-FUNC-002 | B3: Mục kiểu lựa chọn và Đạt/không đạt（合否） không có thao tác tạo quy tắc đỏ có hiệu lực | C3: A. Functional | D3: - Điều kiện: Đăng nhập tài khoản giáo viên có quyền sửa mục. - Dữ liệu test: mục kiểu lựa chọn A/B/C, mục Đạt/không đạt（合否） | E3: TBD | F3: CONFIRMED | G3: BLOCKED | H3: tiêu chí nghiệm thu “Kiểu điểm được hỗ trợ” (AC-G02 «Kiểu điểm được hỗ trợ»); tiêu chí nghiệm thu “Phạm vi từng đợt” (AC-G40 «Phạm vi từng đợt») | I3: A. Functional | J3: test-cases.vi.md | K3: 1. Mở Thiết lập ô nhập（入力欄設定）. 2. Xem hàng Thiết lập điểm đỏ（赤点設定） ở cột mục kiểu lựa chọn A/B/C, mục Đạt/không đạt（合否）. 3. Thử mở URL màn danh sách điểm đỏ của mục kiểu lựa chọn A/B/C bằng ID mục (nếu biết URL). | Lượt chạy | Phạm vi thực hiện và đối chiếu | | --- | --- | | Run: choice | Mục lựa chọn, gồm thử URL trực tiếp ở bước 3 | | Run: passfail | Mục Đạt/không đạt ở bước 1–2 | | L3: 1. Không có thao tác tạo quy tắc đỏ có hiệu lực cho hai mục này. 2. Nếu có endpoint truy cập trực tiếp, server vẫn từ chối tạo/lưu quy tắc cho mục không thuộc loại số; không dùng việc URL không hiển thị làm bằng chứng duy nhất. | O3: 2 | P3: =IF(OR(COUNTIF('Run Log'!$B:$B,A3)<>O3,COUNTIF('Run Log'!$A:$A,"RUN-TC-RS-FUNC-002-choice")<>1,COUNTIFS('Run Log'!$A:$A,"RUN-TC-RS-FUNC-002-choice",'Run Log'!$B:$B,A3,'Run Log'!$C:$C,"choice")<>1,COUNTIF('Run Log'!$A:$A,"RUN-TC-RS-FUNC-002-passfail")<>1,COUNTIFS('Run Log'!$A:$A,"RUN-TC-RS-FUNC-002-passfail",'Run Log'!$B:$B,A3,'Run Log'!$C:$C,"passfail")<>1),"INCOMPLETE",IF(COUNTIFS('Run Log'!$B:$B,A3,'Run Log'!$D:$D,"PASS")=O3,"PASS",IF(COUNTIFS('Run Log'!$B:$B,A3,'Run Log'!$D:$D,"FAIL")>0,"FAIL",IF(COUNTIFS('Run Log'!$B:$B,A3,'Run Log'!$D:$D,"BLOCKED")>0,"BLOCKED",IF(COUNTIFS('Run Log'!$B:$B,A3,'Run Log'!$D:$D,"SKIPPED")>0,"SKIPPED","NOT RUN")))))
A4: TC-RS-FUNC-004 | B4: Thêm quy tắc qua Điều kiện áp dụng（適用条件） và Ngưỡng（基準設定） rồi quay lại danh sách | C4: A. Functional | D4: - Điều kiện: mục số nguyên (M=100) đã có cặp quy tắc cùng áp dụng (dưới 20 và dưới 30) (2 quy tắc). Đăng nhập tài khoản giáo viên có quyền sửa mục. - Dữ liệu test: mục số nguyên (M=100), cặp quy tắc cùng áp dụng (dưới 20 và dưới 30); quy tắc “Cố định 30” (dưới 30) | E4: TBD | F4: CONFIRMED | G4: UNASSESSED | H4: tiêu chí nghiệm thu “Lưu và mở lại nhiều thiết lập” (AC-G04 «Lưu và mở lại nhiều thiết lập») | I4: A. Functional | J4: test-cases.vi.md | K4: 1. Ở danh sách, bấm Thêm thiết lập chi tiết（詳細設定の追加）. 2. Nhập Tên thiết lập（設定名称） "Cố định 30", chọn Toàn bộ đối tượng（全員が対象）, bấm Cập nhật（更新する）. 3. Mở Ngưỡng, chọn Điểm cố định（固定点数）, nhập 30, chọn Nhỏ hơn（未満）, bấm Cập nhật（更新する）. 4. Xem danh sách. | Lượt chạy | Phạm vi thực hiện và đối chiếu | | --- | --- | | Run: Base | Toàn bộ thủ tục theo đúng thứ tự; các đối chứng cùng fixture được kiểm trong cùng lượt, không bỏ bước | | L4: 1. Sau mỗi lần cập nhật, màn quay về danh sách. 2. Dòng mới hiện tên, tóm tắt điều kiện "toàn bộ" và ngưỡng "Điểm cố định: 30 điểm, Nhỏ hơn" đúng với dữ liệu đã lưu. 3. **PROPOSED (đặc tả v2 mục 4.4 “Lưu, đổi thứ tự và xóa”):** dòng mới nằm sau các quy tắc đã có. | O4: 1 | P4: =IF(OR(COUNTIF('Run Log'!$B:$B,A4)<>O4,COUNTIF('Run Log'!$A:$A,"RUN-TC-RS-FUNC-004-Base")<>1,COUNTIFS('Run Log'!$A:$A,"RUN-TC-RS-FUNC-004-Base",'Run Log'!$B:$B,A4,'Run Log'!$C:$C,"Base")<>1),"INCOMPLETE",IF(COUNTIFS('Run Log'!$B:$B,A4,'Run Log'!$D:$D,"PASS")=O4,"PASS",IF(COUNTIFS('Run Log'!$B:$B,A4,'Run Log'!$D:$D,"FAIL")>0,"FAIL",IF(COUNTIFS('Run Log'!$B:$B,A4,'Run Log'!$D:$D,"BLOCKED")>0,"BLOCKED",IF(COUNTIFS('Run Log'!$B:$B,A4,'Run Log'!$D:$D,"SKIPPED")>0,"SKIPPED","NOT RUN")))))
A5: TC-RS-FUNC-005 | B5: Nhiều quy tắc hiển thị theo ưu tiên; đổi thứ tự bằng ▲▼ được lưu | C5: A. Functional | D5: - Điều kiện: mục số nguyên (M=100) có 3 quy tắc tên quy tắc 1, quy tắc 2, quy tắc 3 (tên tạm trong case) theo thứ tự. - Dữ liệu test: mục số nguyên (M=100); quy tắc “Cố định 30” (dưới 30), cặp quy tắc cùng áp dụng (dưới 20 và dưới 30) | E5: Cao | F5: CONFIRMED | G5: UNASSESSED | H5: tiêu chí nghiệm thu “Lưu và mở lại nhiều thiết lập” (AC-G04 «Lưu và mở lại nhiều thiết lập») | I5: A. Functional | J5: test-cases.vi.md | K5: 1. Bấm ▼ ở quy tắc 1. 2. Tải lại trang. 3. Bấm ▲ ở quy tắc 3. 4. Đăng xuất, đăng nhập lại, mở danh sách. | Lượt chạy | Phạm vi thực hiện và đối chiếu | | --- | --- | | Run: Base | Toàn bộ thủ tục theo đúng thứ tự; các đối chứng cùng fixture được kiểm trong cùng lượt, không bỏ bước | | L5: 1. Sau bước 1 thứ tự là quy tắc 2, quy tắc 1, quy tắc 3 và giữ nguyên sau khi tải lại. 2. Sau bước 3 thứ tự là quy tắc 2, quy tắc 3, quy tắc 1 và giữ nguyên khi mở lại. 3. Đổi thứ tự không làm thay kết quả đỏ hiện có (kiểm ở case “Lưu cấu hình không xét; kết quả trước giữ tới lần chạy lại”). | O5: 1 | P5: =IF(OR(COUNTIF('Run Log'!$B:$B,A5)<>O5,COUNTIF('Run Log'!$A:$A,"RUN-TC-RS-FUNC-005-Base")<>1,COUNTIFS('Run Log'!$A:$A,"RUN-TC-RS-FUNC-005-Base",'Run Log'!$B:$B,A5,'Run Log'!$C:$C,"Base")<>1),"INCOMPLETE",IF(COUNTIFS('Run Log'!$B:$B,A5,'Run Log'!$D:$D,"PASS")=O5,"PASS",IF(COUNTIFS('Run Log'!$B:$B,A5,'Run Log'!$D:$D,"FAIL")>0,"FAIL",IF(COUNTIFS('Run Log'!$B:$B,A5,'Run Log'!$D:$D,"BLOCKED")>0,"BLOCKED",IF(COUNTIFS('Run Log'!$B:$B,A5,'Run Log'!$D:$D,"SKIPPED")>0,"SKIPPED","NOT RUN")))))
A6: TC-RS-FUNC-006 | B6: Xóa một quy tắc có xác nhận; Hủy（キャンセル） giữ nguyên | C6: A. Functional | D6: - Điều kiện: mục số nguyên (M=100) có 2 quy tắc. - Dữ liệu test: mục số nguyên (M=100); cặp quy tắc cùng áp dụng (dưới 20 và dưới 30) | E6: Cao | F6: CONFIRMED | G6: UNASSESSED | H6: tiêu chí nghiệm thu “Lưu và mở lại nhiều thiết lập” (AC-G04 «Lưu và mở lại nhiều thiết lập») | I6: A. Functional | J6: test-cases.vi.md | K6: 1. Bấm Xóa（削除） ở quy tắc thứ 2, chọn Hủy（キャンセル）. 2. Bấm Xóa（削除） lại, chọn Xóa（削除する）. | Lượt chạy | Phạm vi thực hiện và đối chiếu | | --- | --- | | Run: cancel | Hủy xóa | | Run: delete | Xác nhận xóa, dựng lại baseline trước lượt này | | L6: 1. Hộp xác nhận nêu thiết lập sẽ bị xóa và kết quả học sinh chỉ cập nhật ở lần xét tiếp theo. 2. Hủy: danh sách giữ 2 quy tắc. 3. Xóa: danh sách còn 1 quy tắc; kết quả đỏ hiện có không đổi cho tới lần xét tiếp theo (case “Xóa quy tắc cuối: giữ kết quả tới lần chạy lại; chạy lại → Không áp dụng”). | O6: 2 | P6: =IF(OR(COUNTIF('Run Log'!$B:$B,A6)<>O6,COUNTIF('Run Log'!$A:$A,"RUN-TC-RS-FUNC-006-cancel")<>1,COUNTIFS('Run Log'!$A:$A,"RUN-TC-RS-FUNC-006-cancel",'Run Log'!$B:$B,A6,'Run Log'!$C:$C,"cancel")<>1,COUNTIF('Run Log'!$A:$A,"RUN-TC-RS-FUNC-006-delete")<>1,COUNTIFS('Run Log'!$A:$A,"RUN-TC-RS-FUNC-006-delete",'Run Log'!$B:$B,A6,'Run Log'!$C:$C,"delete")<>1),"INCOMPLETE",IF(COUNTIFS('Run Log'!$B:$B,A6,'Run Log'!$D:$D,"PASS")=O6,"PASS",IF(COUNTIFS('Run Log'!$B:$B,A6,'Run Log'!$D:$D,"FAIL")>0,"FAIL",IF(COUNTIFS('Run Log'!$B:$B,A6,'Run Log'!$D:$D,"BLOCKED")>0,"BLOCKED",IF(COUNTIFS('Run Log'!$B:$B,A6,'Run Log'!$D:$D,"SKIPPED")>0,"SKIPPED","NOT RUN")))))
A7: TC-RS-FUNC-007 | B7: Quay lại（戻る）/hủy chỉnh sửa không lưu dữ liệu đang nhập | C7: A. Functional | D7: - Điều kiện: mục số nguyên (M=100) có quy tắc “Cố định 30” (dưới 30). - Dữ liệu test: mục số nguyên (M=100); quy tắc “Cố định 30” (dưới 30) | E7: TBD | F7: CONFIRMED | G7: UNASSESSED | H7: tiêu chí nghiệm thu “Lưu và mở lại nhiều thiết lập” (AC-G04 «Lưu và mở lại nhiều thiết lập») | I7: A. Functional | J7: test-cases.vi.md | K7: 1. Mở Ngưỡng của quy tắc “Cố định 30” (dưới 30), đổi 30 thành 35 và đổi sang Nhỏ hơn hoặc bằng（以下）. 2. Bấm Quay lại（戻る）. 3. Mở Điều kiện áp dụng, đổi tên, bấm Quay lại（戻る）. 4. Mở lại hai màn. | Lượt chạy | Phạm vi thực hiện và đối chiếu | | --- | --- | | Run: back-threshold | Quay lại từ màn ngưỡng | | Run: back-condition | Quay lại từ màn điều kiện | | L7: Danh sách và hai màn vẫn hiện giá trị đã lưu trước đó (30, Nhỏ hơn, tên cũ). | O7: 2 | P7: =IF(OR(COUNTIF('Run Log'!$B:$B,A7)<>O7,COUNTIF('Run Log'!$A:$A,"RUN-TC-RS-FUNC-007-back-threshold")<>1,COUNTIFS('Run Log'!$A:$A,"RUN-TC-RS-FUNC-007-back-threshold",'Run Log'!$B:$B,A7,'Run Log'!$C:$C,"back-threshold")<>1,COUNTIF('Run Log'!$A:$A,"RUN-TC-RS-FUNC-007-back-condition")<>1,COUNTIFS('Run Log'!$A:$A,"RUN-TC-RS-FUNC-007-back-condition",'Run Log'!$B:$B,A7,'Run Log'!$C:$C,"back-condition")<>1),"INCOMPLETE",IF(COUNTIFS('Run Log'!$B:$B,A7,'Run Log'!$D:$D,"PASS")=O7,"PASS",IF(COUNTIFS('Run Log'!$B:$B,A7,'Run Log'!$D:$D,"FAIL")>0,"FAIL",IF(COUNTIFS('Run Log'!$B:$B,A7,'Run Log'!$D:$D,"BLOCKED")>0,"BLOCKED",IF(COUNTIFS('Run Log'!$B:$B,A7,'Run Log'!$D:$D,"SKIPPED")>0,"SKIPPED","NOT RUN")))))
A8: TC-RS-FUNC-008 | B8: Điều kiện áp dụng: Toàn bộ đối tượng hoặc giới hạn bằng bộ lọc kế thừa từ tính tự động | C8: A. Functional | D8: - Điều kiện: Đăng nhập tài khoản giáo viên có quyền sửa mục. - Dữ liệu test: các lớp học phần G-A, G-B, G-C, quy tắc có bộ lọc kết hợp (khối 1 hoặc 2, nhóm Nâng cao) | E8: TBD | F8: CONFIRMED | G8: UNASSESSED | H8: tiêu chí nghiệm thu “Đối tượng áp dụng và nhu cầu nguồn” (AC-G05 «Đối tượng áp dụng và nhu cầu nguồn») | I8: A. Functional | J8: test-cases.vi.md | K8: 1. Mở Điều kiện áp dụng của một quy tắc mới. 2. Chọn Toàn bộ đối tượng（全員が対象）, lưu, mở lại. 3. Chọn Giới hạn bằng bộ lọc（特定条件で絞り込む）, bấm Thêm điều kiện lọc（絞り込み条件を追加）, liệt kê các loại lọc có trong danh sách. 4. Cấu hình như quy tắc có bộ lọc kết hợp (khối 1 hoặc 2, nhóm Nâng cao), lưu, mở lại. | Lượt chạy | Phạm vi thực hiện và đối chiếu | | --- | --- | | Run: all | Toàn bộ đối tượng | | Run: filter | Giới hạn bằng bộ lọc | | L8: 1. Hai lựa chọn đối tượng lưu và mở lại đúng. 2. Có các bộ lọc Môn/phân môn（教科・科目）, Khối（学年）, lớp/nhóm và các điều kiện lựa chọn đang được hỗ trợ (đặc tả v2 mục 5.1 “Đối tượng áp dụng”). Danh sách đề xuất (PROPOSED, thiết kế DB v2 mục 3.2 “`apply_condition`”): khối (`hr_grade`), môn (`subject`), phân môn (`sub_subject`), lớp học phần (`group`), lớp chủ nhiệm (`homeroom`), nhóm tổng hợp (`calc_group`), mã lựa chọn của mục (`choice`). 3. Không có trình soạn AND/OR lồng nhau. | O8: 2 | P8: =IF(OR(COUNTIF('Run Log'!$B:$B,A8)<>O8,COUNTIF('Run Log'!$A:$A,"RUN-TC-RS-FUNC-008-all")<>1,COUNTIFS('Run Log'!$A:$A,"RUN-TC-RS-FUNC-008-all",'Run Log'!$B:$B,A8,'Run Log'!$C:$C,"all")<>1,COUNTIF('Run Log'!$A:$A,"RUN-TC-RS-FUNC-008-filter")<>1,COUNTIFS('Run Log'!$A:$A,"RUN-TC-RS-FUNC-008-filter",'Run Log'!$B:$B,A8,'Run Log'!$C:$C,"filter")<>1),"INCOMPLETE",IF(COUNTIFS('Run Log'!$B:$B,A8,'Run Log'!$D:$D,"PASS")=O8,"PASS",IF(COUNTIFS('Run Log'!$B:$B,A8,'Run Log'!$D:$D,"FAIL")>0,"FAIL",IF(COUNTIFS('Run Log'!$B:$B,A8,'Run Log'!$D:$D,"BLOCKED")>0,"BLOCKED",IF(COUNTIFS('Run Log'!$B:$B,A8,'Run Log'!$D:$D,"SKIPPED")>0,"SKIPPED","NOT RUN")))))
A9: TC-RS-FUNC-009 | B9: Điều kiện phân nhánh theo Trung bình（平均点） được lưu cùng bộ nguồn | C9: A. Functional | D9: - Điều kiện: Đăng nhập tài khoản giáo viên có quyền sửa mục. Có nguồn tổng hợp mặc định. - Dữ liệu test: cặp quy tắc phân nhánh theo trung bình 60, bản tổng hợp mới nhất chưa chốt (trung bình 62) | E9: TBD | F9: CONFIRMED | G9: UNASSESSED | H9: tiêu chí nghiệm thu “Đúng phạm vi tham chiếu” (AC-G12 «Đúng phạm vi tham chiếu») | I9: A. Functional | J9: test-cases.vi.md | K9: 1. Tạo quy tắc "Trung bình dưới 60": thêm bộ lọc Môn（教科・科目）= Toán（数学） và điều kiện Trung bình（平均点）. 2. Chọn Thời kỳ tổng hợp（集計対象時期）= 1学期期末 (cuối kỳ học kỳ 1), Thiết lập tổng hợp thứ hạng（順位集計設定）= 評点集計 (tổng hợp điểm đánh giá), Nhóm học sinh được tổng hợp — 集計対象（母集団）= ホームルーム (lớp chủ nhiệm; file Figma cũ ghi HR毎). 3. Nhập mốc 60, dấu Nhỏ hơn（未満）, lưu. 4. Tạo quy tắc thứ hai với mốc 60, dấu Từ mức này trở lên（以上）. 5. Mở lại cả hai. | Lượt chạy | Phạm vi thực hiện và đối chiếu | | --- | --- | | Run: below60 | Điều kiện dưới 60 | | Run: from60 | Điều kiện từ 60 | | L9: 1. Cả hai quy tắc lưu được, là hai dòng riêng trong danh sách (không phải một form hai nhánh). 2. Mở lại giữ đủ bộ nguồn, mốc, dấu. 3. Không có lựa chọn Kết quả tổng hợp dùng để tham chiếu（参照する集計結果） (đặc tả v2 mục 3 “Bản đồ màn hình và luồng thao tác”, mục 5.5 “Chọn bản nguồn”). | O9: 2 | P9: =IF(OR(COUNTIF('Run Log'!$B:$B,A9)<>O9,COUNTIF('Run Log'!$A:$A,"RUN-TC-RS-FUNC-009-below60")<>1,COUNTIFS('Run Log'!$A:$A,"RUN-TC-RS-FUNC-009-below60",'Run Log'!$B:$B,A9,'Run Log'!$C:$C,"below60")<>1,COUNTIF('Run Log'!$A:$A,"RUN-TC-RS-FUNC-009-from60")<>1,COUNTIFS('Run Log'!$A:$A,"RUN-TC-RS-FUNC-009-from60",'Run Log'!$B:$B,A9,'Run Log'!$C:$C,"from60")<>1),"INCOMPLETE",IF(COUNTIFS('Run Log'!$B:$B,A9,'Run Log'!$D:$D,"PASS")=O9,"PASS",IF(COUNTIFS('Run Log'!$B:$B,A9,'Run Log'!$D:$D,"FAIL")>0,"FAIL",IF(COUNTIFS('Run Log'!$B:$B,A9,'Run Log'!$D:$D,"BLOCKED")>0,"BLOCKED",IF(COUNTIFS('Run Log'!$B:$B,A9,'Run Log'!$D:$D,"SKIPPED")>0,"SKIPPED","NOT RUN")))))
A10: TC-RS-FUNC-010 | B10: Điều kiện Tỷ lệ điểm của nhóm（集団の得点率） được lưu cùng bộ nguồn | C10: A. Functional | D10: - Điều kiện: Đăng nhập tài khoản giáo viên có quyền sửa mục. - Dữ liệu test: quy tắc theo tỷ lệ điểm của nhóm từ 65% | E10: TBD | F10: CONFIRMED | G10: UNASSESSED | H10: tiêu chí nghiệm thu “Đúng phạm vi tham chiếu” (AC-G12 «Đúng phạm vi tham chiếu») | I10: A. Functional | J10: test-cases.vi.md | K10: 1. Tạo quy tắc với điều kiện Tỷ lệ điểm của nhóm（集団の得点率）, nguồn mặc định, mốc 65, dấu Từ mức này trở lên（以上）. 2. Lưu, mở lại. | Lượt chạy | Phạm vi thực hiện và đối chiếu | | --- | --- | | Run: Base | Toàn bộ thủ tục theo đúng thứ tự; các đối chứng cùng fixture được kiểm trong cùng lượt, không bỏ bước | | L10: Lưu và mở lại đúng loại điều kiện, nguồn, mốc 65 và dấu. Không có tùy chọn chọn cách tính A/B. | O10: 1 | P10: =IF(OR(COUNTIF('Run Log'!$B:$B,A10)<>O10,COUNTIF('Run Log'!$A:$A,"RUN-TC-RS-FUNC-010-Base")<>1,COUNTIFS('Run Log'!$A:$A,"RUN-TC-RS-FUNC-010-Base",'Run Log'!$B:$B,A10,'Run Log'!$C:$C,"Base")<>1),"INCOMPLETE",IF(COUNTIFS('Run Log'!$B:$B,A10,'Run Log'!$D:$D,"PASS")=O10,"PASS",IF(COUNTIFS('Run Log'!$B:$B,A10,'Run Log'!$D:$D,"FAIL")>0,"FAIL",IF(COUNTIFS('Run Log'!$B:$B,A10,'Run Log'!$D:$D,"BLOCKED")>0,"BLOCKED",IF(COUNTIFS('Run Log'!$B:$B,A10,'Run Log'!$D:$D,"SKIPPED")>0,"SKIPPED","NOT RUN")))))
A11: TC-RS-FUNC-011 | B11: Chọn loại ngưỡng làm thay đổi vùng nhập | C11: A. Functional | D11: - Điều kiện: Mở Ngưỡng của một quy tắc. - Dữ liệu test: — | E11: TBD | F11: CONFIRMED | G11: UNASSESSED | H11: đặc tả v2 mục 5.6 “Khi nào không cần nguồn?”, mục 6.1 “Thành phần chung của màn ngưỡng” | I11: A. Functional | J11: test-cases.vi.md | K11: 1. Chọn Điểm cố định（固定点数）. 2. Chọn Tỷ lệ điểm tối đa（得点率）. 3. Chọn Công thức（計算式）. | Lượt chạy | Phạm vi thực hiện và đối chiếu | | --- | --- | | Run: fixed | Chọn cố định | | Run: ratio | Chọn tỷ lệ | | Run: formula | Chọn công thức | | L11: 1. Cố định: có ô ngưỡng và dấu so sánh; không có vùng nguồn trung bình, không có xử lý phần lẻ. 2. Tỷ lệ: có ô %, xử lý phần lẻ, dấu so sánh; không có vùng nguồn trung bình. 3. Công thức: có vùng nguồn trung bình, bảng dòng công thức, dấu so sánh. | O11: 3 | P11: =IF(OR(COUNTIF('Run Log'!$B:$B,A11)<>O11,COUNTIF('Run Log'!$A:$A,"RUN-TC-RS-FUNC-011-fixed")<>1,COUNTIFS('Run Log'!$A:$A,"RUN-TC-RS-FUNC-011-fixed",'Run Log'!$B:$B,A11,'Run Log'!$C:$C,"fixed")<>1,COUNTIF('Run Log'!$A:$A,"RUN-TC-RS-FUNC-011-ratio")<>1,COUNTIFS('Run Log'!$A:$A,"RUN-TC-RS-FUNC-011-ratio",'Run Log'!$B:$B,A11,'Run Log'!$C:$C,"ratio")<>1,COUNTIF('Run Log'!$A:$A,"RUN-TC-RS-FUNC-011-formula")<>1,COUNTIFS('Run Log'!$A:$A,"RUN-TC-RS-FUNC-011-formula",'Run Log'!$B:$B,A11,'Run Log'!$C:$C,"formula")<>1),"INCOMPLETE",IF(COUNTIFS('Run Log'!$B:$B,A11,'Run Log'!$D:$D,"PASS")=O11,"PASS",IF(COUNTIFS('Run Log'!$B:$B,A11,'Run Log'!$D:$D,"FAIL")>0,"FAIL",IF(COUNTIFS('Run Log'!$B:$B,A11,'Run Log'!$D:$D,"BLOCKED")>0,"BLOCKED",IF(COUNTIFS('Run Log'!$B:$B,A11,'Run Log'!$D:$D,"SKIPPED")>0,"SKIPPED","NOT RUN")))))
A12: TC-RS-FUNC-012 | B12: Công thức: thêm/xóa dòng, kết quả dòng cuối là ngưỡng | C12: A. Functional | D12: - Điều kiện: Mở Ngưỡng loại Công thức（計算式）. - Dữ liệu test: quy tắc công thức hai dòng (trung bình ÷ 2 × 0.8) | E12: Cao | F12: CONFIRMED | G12: UNASSESSED | H12: tiêu chí nghiệm thu “Công thức theo dòng và phần lẻ” (AC-G16 «Công thức theo dòng và phần lẻ») | I12: A. Functional | J12: test-cases.vi.md | K12: 1. Cấu hình dòng 1 và dòng 2 như quy tắc công thức hai dòng (trung bình ÷ 2 × 0.8), lưu. 2. Mở lại; bấm Thêm công thức（計算式を追加） để có dòng 3, rồi xóa dòng 3, lưu. 3. Xem tóm tắt ở danh sách. | Lượt chạy | Phạm vi thực hiện và đối chiếu | | --- | --- | | Run: Base | Toàn bộ thủ tục theo đúng thứ tự; các đối chứng cùng fixture được kiểm trong cùng lượt, không bỏ bước | | L12: 1. Lưu được 2 dòng; mở lại giữ vế trái, phép toán, vế phải và xử lý phần lẻ từng dòng (chi tiết form là PROPOSED theo thiết kế). 2. Danh sách tóm tắt đủ các dòng và dấu so sánh (PROPOSED; không dùng làm oracle nghiệp vụ nếu đặc tả chưa chốt bố cục tóm tắt). 3. Khi xét, `T` = kết quả dòng cuối; phép tính và xử lý phần lẻ phải tuân theo AC-G16 và case “Công thức hai dòng theo Figma: (A÷2)×0.8, dòng 1 làm tròn xuống”. | O12: 1 | P12: =IF(OR(COUNTIF('Run Log'!$B:$B,A12)<>O12,COUNTIF('Run Log'!$A:$A,"RUN-TC-RS-FUNC-012-Base")<>1,COUNTIFS('Run Log'!$A:$A,"RUN-TC-RS-FUNC-012-Base",'Run Log'!$B:$B,A12,'Run Log'!$C:$C,"Base")<>1),"INCOMPLETE",IF(COUNTIFS('Run Log'!$B:$B,A12,'Run Log'!$D:$D,"PASS")=O12,"PASS",IF(COUNTIFS('Run Log'!$B:$B,A12,'Run Log'!$D:$D,"FAIL")>0,"FAIL",IF(COUNTIFS('Run Log'!$B:$B,A12,'Run Log'!$D:$D,"BLOCKED")>0,"BLOCKED",IF(COUNTIFS('Run Log'!$B:$B,A12,'Run Log'!$D:$D,"SKIPPED")>0,"SKIPPED","NOT RUN")))))
A13: TC-RS-FUNC-013 | B13: Dấu so sánh Nhỏ hơn（未満）/Nhỏ hơn hoặc bằng（以下） được lưu và hiển thị | C13: A. Functional | D13: - Điều kiện: Có quy tắc “Cố định 30” (dưới 30). - Dữ liệu test: quy tắc “Cố định 30” (dưới 30), quy tắc cố định 30 với Nhỏ hơn hoặc bằng（以下） | E13: TBD | F13: CONFIRMED | G13: UNASSESSED | H13: đặc tả v2 mục 6.1 “Thành phần chung của màn ngưỡng” | I13: A. Functional | J13: test-cases.vi.md | K13: 1. Đổi dấu của quy tắc “Cố định 30” (dưới 30) sang Nhỏ hơn hoặc bằng（以下）, lưu, mở lại. 2. Đổi lại Nhỏ hơn（未満）, lưu, mở lại. | Lượt chạy | Phạm vi thực hiện và đối chiếu | | --- | --- | | Run: lt | Dấu nhỏ hơn | | Run: le | Dấu nhỏ hơn hoặc bằng | | L13: Dấu đã chọn được lưu, hiển thị đúng ở form và tóm tắt danh sách. Tác động lên kết quả: case “Ngưỡng cố định 30: S = 29 / 30 / 31 với `<` và `≤`”. | O13: 2 | P13: =IF(OR(COUNTIF('Run Log'!$B:$B,A13)<>O13,COUNTIF('Run Log'!$A:$A,"RUN-TC-RS-FUNC-013-lt")<>1,COUNTIFS('Run Log'!$A:$A,"RUN-TC-RS-FUNC-013-lt",'Run Log'!$B:$B,A13,'Run Log'!$C:$C,"lt")<>1,COUNTIF('Run Log'!$A:$A,"RUN-TC-RS-FUNC-013-le")<>1,COUNTIFS('Run Log'!$A:$A,"RUN-TC-RS-FUNC-013-le",'Run Log'!$B:$B,A13,'Run Log'!$C:$C,"le")<>1),"INCOMPLETE",IF(COUNTIFS('Run Log'!$B:$B,A13,'Run Log'!$D:$D,"PASS")=O13,"PASS",IF(COUNTIFS('Run Log'!$B:$B,A13,'Run Log'!$D:$D,"FAIL")>0,"FAIL",IF(COUNTIFS('Run Log'!$B:$B,A13,'Run Log'!$D:$D,"BLOCKED")>0,"BLOCKED",IF(COUNTIFS('Run Log'!$B:$B,A13,'Run Log'!$D:$D,"SKIPPED")>0,"SKIPPED","NOT RUN")))))
A14: TC-RS-FUNC-014 | B14: Quy tắc mới chỉ có điều kiện, chưa có ngưỡng, không tham gia xét | C14: A. Functional | D14: - Điều kiện chung: trường A/năm 2026, mục số nguyên TD-ITEM-01 (M=100), S01 có điểm 29; giáo viên có quyền sửa rule và chạy xét lại. Hai tab cùng phạm vi mục/kỳ. Mỗi biến thể có bản reset riêng, đúng hai rule Toàn bộ với dấu `<`; ghi identity rule ưu tiên 1 và rule đối chứng ưu tiên 2. Phạm vi trích xuất chỉ gồm ô này để ô đỏ khác không ảnh hưởng bộ lọc. - `incomplete-excluded`: rule ưu tiên 1 chỉ lưu điều kiện, chưa có ngưỡng; rule đối chứng ưu tiên 2 có T=30. Đây là fixture TD-RULE-13/TD-RULE-01. - `complete-deleted-stale`: rule ưu tiên 1 hoàn chỉnh T=30, rule đối chứng ưu tiên 2 T=20; chạy baseline S01=29 → Đỏ theo rule ưu tiên 1. - `incomplete-deleted-stale`: rule ưu tiên 1 chỉ có điều kiện, rule đối chứng ưu tiên 2 T=20; chạy baseline S01=29 → Không đỏ theo rule đối chứng. T=20 là cấu hình riêng của hai biến thể stale-form, không thay TD-RULE-01 dùng chung. | E14: Cao | F14: CONFIRMED | G14: BLOCKED | H14: đặc tả v2 mục 4.4 “Lưu, đổi thứ tự và xóa”; tiêu chí nghiệm thu “Lưu và mở lại nhiều thiết lập” (AC-G04 «Lưu và mở lại nhiều thiết lập») | I14: A. Functional | J14: test-cases.vi.md | K14: 1. Với `incomplete-excluded`, dựng fixture riêng, xem dòng chưa hoàn chỉnh; đăng ký S01=29 và đọc kết quả, identity rule/ngưỡng đã dùng cùng đầu ra trích xuất. 2. Với `complete-deleted-stale`, reset và xác nhận baseline Đỏ/T=30. Mở form ngưỡng của rule ưu tiên 1 ở tab A. Xóa đúng rule đó ở tab B, rồi gửi lưu T=30 từ form cũ ở tab A. Reload danh sách và đọc trạng thái rule; trước khi chạy xét lại, đọc điểm/kết quả đã hoàn tất của S01. 3. Chạy xét lại thành công cho đúng ô của `complete-deleted-stale`; đọc identity rule/ngưỡng được chọn. Chạy trích xuất một lượt tắt lọc để thấy điểm và dấu, một lượt bật lọc đỏ để kiểm membership của S01. 4. Với `incomplete-deleted-stale`, reset và xác nhận baseline Không đỏ/T=20. Mở form ngưỡng của rule nhập dở ở tab A, nhập T=40 nhưng **chưa lưu**. Xóa đúng rule nhập dở ở tab B, rồi gửi T=40 từ form cũ ở tab A. Reload danh sách và đọc trạng thái rule. 5. Chạy xét lại thành công cho đúng ô của `incomplete-deleted-stale`; đọc identity rule/ngưỡng và thực hiện hai lượt trích xuất tắt/bật lọc như bước 3. Lưu bằng chứng riêng cho từng biến thể, không dùng kết quả của biến thể trước. | Lượt chạy | Phạm vi thực hiện và đối chiếu | | --- | --- | | Run: incomplete-excluded | Nhánh incomplete-excluded trong thủ tục và Expected của case; thực hiện các bước chuẩn bị chung trước nhánh | | Run: complete-deleted-stale | Nhánh complete-deleted-stale trong thủ tục và Expected của case; thực hiện các bước chuẩn bị chung trước nhánh | | Run: incomplete-deleted-stale | Nhánh incomplete-deleted-stale trong thủ tục và Expected của case; thực hiện các bước chuẩn bị chung trước nhánh | | L14: 1. `incomplete-excluded`: dòng nhập dở hiện chưa thiết lập và cho mở ngưỡng; không tạo ngưỡng 0 ngầm. Bộ xét chọn đúng rule đối chứng T=30, S01=29 Đỏ; rule nhập dở không tham gia xét. 2. `complete-deleted-stale`: lưu form cũ không phục hồi rule đã xóa trong danh sách hoặc bộ xét. Trước lần xét lại, S01 vẫn giữ điểm 29 và kết quả Đỏ/T=30 đã hoàn tất. Sau lần xét lại, bộ xét chọn đúng identity rule đối chứng T=20 → **Không đỏ**; lượt tắt lọc hiện 29 không dấu đỏ, lượt bật lọc không có S01. 3. `incomplete-deleted-stale`: T=40 gửi từ form cũ không làm rule nhập dở đã xóa sống lại hoặc trở thành rule hoàn chỉnh. Sau lần xét lại, bộ xét vẫn chọn đúng rule đối chứng T=20 → **Không đỏ**, điểm 29 giữ nguyên; lượt tắt lọc không có dấu đỏ, lượt bật lọc không có S01. Nếu rule 40 bị phục hồi thì 29<40 sẽ Đỏ, nên không được PASS trường hợp đó dù danh sách đã ẩn rule. 4. Rule đối chứng giữ nguyên cấu hình/identity ở cả hai biến thể stale-form. Nếu từ chối form cũ, thông báo an toàn; không áp đặt mã HTTP hoặc enum/schema chưa được xác nhận. Thiếu seam gửi form, chạy xét hoặc reader đáng tin thì ghi BLOCKED cho biến thể liên quan. | O14: 3 | P14: =IF(OR(COUNTIF('Run Log'!$B:$B,A14)<>O14,COUNTIF('Run Log'!$A:$A,"RUN-TC-RS-FUNC-014-incomplete-excluded")<>1,COUNTIFS('Run Log'!$A:$A,"RUN-TC-RS-FUNC-014-incomplete-excluded",'Run Log'!$B:$B,A14,'Run Log'!$C:$C,"incomplete-excluded")<>1,COUNTIF('Run Log'!$A:$A,"RUN-TC-RS-FUNC-014-complete-deleted-stale")<>1,COUNTIFS('Run Log'!$A:$A,"RUN-TC-RS-FUNC-014-complete-deleted-stale",'Run Log'!$B:$B,A14,'Run Log'!$C:$C,"complete-deleted-stale")<>1,COUNTIF('Run Log'!$A:$A,"RUN-TC-RS-FUNC-014-incomplete-deleted-stale")<>1,COUNTIFS('Run Log'!$A:$A,"RUN-TC-RS-FUNC-014-incomplete-deleted-stale",'Run Log'!$B:$B,A14,'Run Log'!$C:$C,"incomplete-deleted-stale")<>1),"INCOMPLETE",IF(COUNTIFS('Run Log'!$B:$B,A14,'Run Log'!$D:$D,"PASS")=O14,"PASS",IF(COUNTIFS('Run Log'!$B:$B,A14,'Run Log'!$D:$D,"FAIL")>0,"FAIL",IF(COUNTIFS('Run Log'!$B:$B,A14,'Run Log'!$D:$D,"BLOCKED")>0,"BLOCKED",IF(COUNTIFS('Run Log'!$B:$B,A14,'Run Log'!$D:$D,"SKIPPED")>0,"SKIPPED","NOT RUN")))))
A15: TC-RS-FUNC-015 | B15: Quy trình vận hành dùng trung bình: tắt tự tổng hợp → nút xanh → nút cam | C15: A. Functional | D15: - Điều kiện: mục số nguyên (M=100) có cặp quy tắc phân nhánh theo trung bình 60. Điểm của nhóm HR1 đã đầy đủ. Không có bản chốt cho nguồn mặc định. Đăng nhập tài khoản có quyền chạy hàng loạt. - Dữ liệu test: mục số nguyên (M=100); cặp quy tắc phân nhánh theo trung bình 60, các lớp chủ nhiệm HR1, HR2, học sinh S01–S05 | E15: Cao | F15: CONFIRMED | G15: UNASSESSED | H15: tiêu chí nghiệm thu “Thứ tự đánh giá tương đối” (AC-G25 «Thứ tự đánh giá tương đối») | I15: A. Functional | J15: test-cases.vi.md | K15: 1. Thiết lập tổng hợp thứ hạng（順位集計設定）→ Thiết lập chi tiết（詳細設定）: đặt tự tổng hợp khi đăng ký điểm là Không thực hiện（実行しない）. 2. Ở Tổng hợp thành tích（成績集計）, chọn Khối 1, kỳ 1学期期末 (cuối kỳ học kỳ 1), bấm Thực hiện tổng hợp（集計実行）, chờ hoàn tất. 3. Bấm Thực hiện tính toán tự động（自動算出実行）, chờ hoàn tất. 4. Xem kết quả ở ba đầu ra. 5. Sau bước 3, xem lần chạy tổng hợp gần nhất hiển thị ở Tổng hợp thành tích（成績集計）. | Lượt chạy | Phạm vi thực hiện và đối chiếu | | --- | --- | | Run: Base | Toàn bộ thủ tục theo đúng thứ tự; các đối chứng cùng fixture được kiểm trong cùng lượt, không bỏ bước | | L15: 1. Sau bước 2 (chỉ nút xanh), kết quả đỏ chưa thay đổi. 2. Sau bước 3, mỗi ô của S01–S05 có kết quả theo nhánh đúng với `A` của tổng hợp vừa chạy. 3. Ba đầu ra hiển thị cùng kết quả mới. 4. (Theo tiêu chí nghiệm thu “Thứ tự đánh giá tương đối”) Bước 3 không tự chạy lại Thực hiện tổng hợp（集計実行） hay thêm lượt xét thứ hai, kể cả khi tính tự động làm đổi điểm dùng cho trung bình: lần chạy tổng hợp gần nhất vẫn là lần ở bước 2. Muốn dùng trung bình mới thì người dùng chạy lại quy trình. | O15: 1 | P15: =IF(OR(COUNTIF('Run Log'!$B:$B,A15)<>O15,COUNTIF('Run Log'!$A:$A,"RUN-TC-RS-FUNC-015-Base")<>1,COUNTIFS('Run Log'!$A:$A,"RUN-TC-RS-FUNC-015-Base",'Run Log'!$B:$B,A15,'Run Log'!$C:$C,"Base")<>1),"INCOMPLETE",IF(COUNTIFS('Run Log'!$B:$B,A15,'Run Log'!$D:$D,"PASS")=O15,"PASS",IF(COUNTIFS('Run Log'!$B:$B,A15,'Run Log'!$D:$D,"FAIL")>0,"FAIL",IF(COUNTIFS('Run Log'!$B:$B,A15,'Run Log'!$D:$D,"BLOCKED")>0,"BLOCKED",IF(COUNTIFS('Run Log'!$B:$B,A15,'Run Log'!$D:$D,"SKIPPED")>0,"SKIPPED","NOT RUN")))))
A16: TC-RS-FUNC-016 | B16: Đăng ký/sửa điểm trực tiếp ở màn lớp kích hoạt xét | C16: A. Functional | D16: - Điều kiện: mục số nguyên (M=100) có quy tắc “Cố định 30” (dưới 30); mục số nguyên (M=100) không có quy tắc tính tự động. - Dữ liệu test: mục số nguyên (M=100); quy tắc “Cố định 30” (dưới 30), học sinh S01 (điểm 29), học sinh S03 (điểm 31) | E16: Cao | F16: CONFIRMED | G16: UNASSESSED | H16: tiêu chí nghiệm thu “Bao phủ đường đăng ký và chạy lại” (AC-G23 «Bao phủ đường đăng ký và chạy lại») | I16: A. Functional | J16: test-cases.vi.md | K16: 1. Ở màn đăng ký điểm của lớp G-A, nhập S01=29, S03=31, lưu. 2. Xem trích xuất. | Lượt chạy | Phạm vi thực hiện và đối chiếu | | --- | --- | | Run: Base | Toàn bộ thủ tục theo đúng thứ tự; các đối chứng cùng fixture được kiểm trong cùng lượt, không bỏ bước | | L16: Sau khi lưu thành công: S01 Đỏ, S03 Không đỏ. Đây là đường đăng ký trực tiếp với quy tắc cố định, nên không yêu cầu nguồn trung bình hoặc nút cam; không suy rộng kết luận này cho case dùng trung bình/tỷ lệ nhóm. | O16: 1 | P16: =IF(OR(COUNTIF('Run Log'!$B:$B,A16)<>O16,COUNTIF('Run Log'!$A:$A,"RUN-TC-RS-FUNC-016-Base")<>1,COUNTIFS('Run Log'!$A:$A,"RUN-TC-RS-FUNC-016-Base",'Run Log'!$B:$B,A16,'Run Log'!$C:$C,"Base")<>1),"INCOMPLETE",IF(COUNTIFS('Run Log'!$B:$B,A16,'Run Log'!$D:$D,"PASS")=O16,"PASS",IF(COUNTIFS('Run Log'!$B:$B,A16,'Run Log'!$D:$D,"FAIL")>0,"FAIL",IF(COUNTIFS('Run Log'!$B:$B,A16,'Run Log'!$D:$D,"BLOCKED")>0,"BLOCKED",IF(COUNTIFS('Run Log'!$B:$B,A16,'Run Log'!$D:$D,"SKIPPED")>0,"SKIPPED","NOT RUN")))))
A17: TC-RS-FUNC-017 | B17: Nhập CSV điểm lớp học phần (NB) kích hoạt xét | C17: A. Functional | D17: - Điều kiện: mục số nguyên (M=100) có quy tắc “Cố định 30” (dưới 30). Chạy hai lần: (a) trường có tính tự động, (b) trường không có tính tự động. - Dữ liệu test: mục số nguyên (M=100); quy tắc “Cố định 30” (dưới 30), học sinh S01 (điểm 29) | E17: Cao | F17: CONFIRMED | G17: UNASSESSED | H17: tiêu chí nghiệm thu “Bao phủ đường đăng ký và chạy lại” (AC-G23 «Bao phủ đường đăng ký và chạy lại») | I17: A. Functional | J17: test-cases.vi.md | K17: 1. Mở Đăng ký thành tích bằng CSV（成績CSV登録） của lớp G-A, nhập CSV với S01=29. 2. Xem kết quả ở trích xuất. 3. Nhập lại CSV với S01=31, xem kết quả. | Lượt chạy | Phạm vi thực hiện và đối chiếu | | --- | --- | | Run: auto-on | Trường có tính tự động, thực hiện toàn bộ chuỗi CSV | | Run: auto-off | Trường không có tính tự động, cùng chuỗi CSV | | L17: 1–2. Nhập thành công → S01 được xét: Đỏ, ở cả (a) và (b) (không phụ thuộc việc trường có tính tự động). 3. S01 Không đỏ; không còn dấu đỏ cũ. Điểm và kết quả nhất quán theo ranh giới giao dịch hiện có (tiêu chí nghiệm thu “Lưu thành công và thông báo an toàn”). | O17: 2 | P17: =IF(OR(COUNTIF('Run Log'!$B:$B,A17)<>O17,COUNTIF('Run Log'!$A:$A,"RUN-TC-RS-FUNC-017-auto-on")<>1,COUNTIFS('Run Log'!$A:$A,"RUN-TC-RS-FUNC-017-auto-on",'Run Log'!$B:$B,A17,'Run Log'!$C:$C,"auto-on")<>1,COUNTIF('Run Log'!$A:$A,"RUN-TC-RS-FUNC-017-auto-off")<>1,COUNTIFS('Run Log'!$A:$A,"RUN-TC-RS-FUNC-017-auto-off",'Run Log'!$B:$B,A17,'Run Log'!$C:$C,"auto-off")<>1),"INCOMPLETE",IF(COUNTIFS('Run Log'!$B:$B,A17,'Run Log'!$D:$D,"PASS")=O17,"PASS",IF(COUNTIFS('Run Log'!$B:$B,A17,'Run Log'!$D:$D,"FAIL")>0,"FAIL",IF(COUNTIFS('Run Log'!$B:$B,A17,'Run Log'!$D:$D,"BLOCKED")>0,"BLOCKED",IF(COUNTIFS('Run Log'!$B:$B,A17,'Run Log'!$D:$D,"SKIPPED")>0,"SKIPPED","NOT RUN")))))
A18: TC-RS-FUNC-018 | B18: Liên kết kết quả chấm bài thi kích hoạt xét | C18: A. Functional | D18: - Điều kiện: Có bài thi đã chấm liên kết tới mục số nguyên (M=100) cho lớp G-A và lớp G-C; quy tắc “Cố định 30” (dưới 30) trên mục số nguyên (M=100). G-A đủ thiết lập để AutoRating chạy. G-C được chuẩn bị để `createArgument` không trả lớp này (ví dụ chưa đăng ký thiết lập lớp học bắt buộc（入力必須の授業設定）), nên AutoRating bị bỏ qua. - Dữ liệu test: mục số nguyên (M=100); quy tắc “Cố định 30” (dưới 30), các lớp học phần G-A, G-B, G-C, học sinh S01 (điểm 29) | E18: Cao | F18: CONFIRMED | G18: BLOCKED | H18: tiêu chí nghiệm thu “Bao phủ đường đăng ký và chạy lại” (AC-G23 «Bao phủ đường đăng ký và chạy lại») | I18: A. Functional | J18: test-cases.vi.md | K18: 1. Liên kết kết quả chấm của G-A với S01=29 (quy tắc cố định quy tắc “Cố định 30” (dưới 30)), gồm trường hợp lớp không có quy tắc tính tự động. 2. Liên kết kết quả chấm của G-C với một học sinh của G-C = 28. 3. Xem điểm đã ghi và kết quả đỏ của hai lớp. 4. (Tùy chọn) Lặp lại với quy tắc cần trung bình. | Lượt chạy | Phạm vi thực hiện và đối chiếu | | --- | --- | | Run: linked | Liên kết điểm ở G-A | | Run: auto-skipped | Nhánh AutoRating bỏ qua ở G-C | | L18: 1. S01 Đỏ. 2–3. Điểm 28 của G-C đã được ghi và ô đó được xét → Đỏ, dù AutoRating bị bỏ qua. Không có ô đã ghi nào ở G-C bị để lại không có kết quả. 4. Quy tắc cần trung bình: liên kết không chạy tổng hợp thứ hạng nên trung bình có thể cũ — việc chấp nhận trung bình cũ chưa chốt, phần này TBD, không đánh PASS/FAIL. | O18: 2 | P18: =IF(OR(COUNTIF('Run Log'!$B:$B,A18)<>O18,COUNTIF('Run Log'!$A:$A,"RUN-TC-RS-FUNC-018-linked")<>1,COUNTIFS('Run Log'!$A:$A,"RUN-TC-RS-FUNC-018-linked",'Run Log'!$B:$B,A18,'Run Log'!$C:$C,"linked")<>1,COUNTIF('Run Log'!$A:$A,"RUN-TC-RS-FUNC-018-auto-skipped")<>1,COUNTIFS('Run Log'!$A:$A,"RUN-TC-RS-FUNC-018-auto-skipped",'Run Log'!$B:$B,A18,'Run Log'!$C:$C,"auto-skipped")<>1),"INCOMPLETE",IF(COUNTIFS('Run Log'!$B:$B,A18,'Run Log'!$D:$D,"PASS")=O18,"PASS",IF(COUNTIFS('Run Log'!$B:$B,A18,'Run Log'!$D:$D,"FAIL")>0,"FAIL",IF(COUNTIFS('Run Log'!$B:$B,A18,'Run Log'!$D:$D,"BLOCKED")>0,"BLOCKED",IF(COUNTIFS('Run Log'!$B:$B,A18,'Run Log'!$D:$D,"SKIPPED")>0,"SKIPPED","NOT RUN")))))
A19: TC-RS-FUNC-019 | B19: Lưu lựa chọn điểm tối đa của lớp khi đăng ký điểm kích hoạt xét | C19: A. Functional | D19: - Điều kiện: mục điểm đơn vị (đơn vị U1 có M riêng 40) có quy tắc tỷ lệ 30% (30%). Lớp G-B chưa dùng lựa chọn lớp; S06 có điểm U1 = 14 (M=40 → T=12 → Không đỏ). - Dữ liệu test: mục điểm đơn vị (đơn vị U1 có M riêng 40), quy tắc tỷ lệ 30% | E19: Cao | F19: CONFIRMED | G19: UNASSESSED | H19: tiêu chí nghiệm thu “Trigger khi đổi điểm tối đa/đơn vị” (AC-G24 «Trigger khi đổi điểm tối đa/đơn vị») | I19: A. Functional | J19: test-cases.vi.md | K19: 1. Ở màn đăng ký điểm lớp G-B, chọn lựa chọn lớp M=50 cho U1, lưu. 2. Xem kết quả S06. | Lượt chạy | Phạm vi thực hiện và đối chiếu | | --- | --- | | Run: Base | Toàn bộ thủ tục theo đúng thứ tự; các đối chứng cùng fixture được kiểm trong cùng lượt, không bỏ bước | | L19: Sau khi lưu thành công: M=50 → T=15 → S06=14 Đỏ. | O19: 1 | P19: =IF(OR(COUNTIF('Run Log'!$B:$B,A19)<>O19,COUNTIF('Run Log'!$A:$A,"RUN-TC-RS-FUNC-019-Base")<>1,COUNTIFS('Run Log'!$A:$A,"RUN-TC-RS-FUNC-019-Base",'Run Log'!$B:$B,A19,'Run Log'!$C:$C,"Base")<>1),"INCOMPLETE",IF(COUNTIFS('Run Log'!$B:$B,A19,'Run Log'!$D:$D,"PASS")=O19,"PASS",IF(COUNTIFS('Run Log'!$B:$B,A19,'Run Log'!$D:$D,"FAIL")>0,"FAIL",IF(COUNTIFS('Run Log'!$B:$B,A19,'Run Log'!$D:$D,"BLOCKED")>0,"BLOCKED",IF(COUNTIFS('Run Log'!$B:$B,A19,'Run Log'!$D:$D,"SKIPPED")>0,"SKIPPED","NOT RUN")))))
A20: TC-RS-FUNC-020 | B20: Lưu Thiết lập điểm tối đa hàng loạt（満点一括設定） xếp hàng tính toán rồi mới có kết quả mới | C20: A. Functional | D20: - Điều kiện: Trường có chức năng Thiết lập điểm tối đa hàng loạt（満点一括設定） (`/admin/grade/lesson_group/setting?setting_type=change_max_score`); tài khoản có quyền chạy hàng loạt; quy tắc tỷ lệ 30% trên mục điểm đơn vị (đơn vị U1 có M riêng 40). - Dữ liệu test: mục điểm đơn vị (đơn vị U1 có M riêng 40), quy tắc tỷ lệ 30% | E20: Cao | F20: CONFIRMED | G20: UNASSESSED | H20: tiêu chí nghiệm thu “Trigger khi đổi điểm tối đa/đơn vị” (AC-G24 «Trigger khi đổi điểm tối đa/đơn vị») | I20: A. Functional | J20: test-cases.vi.md | K20: 1. Lưu M=50 cho các lớp/kỳ được phép. 2. Ngay sau khi lưu (trước khi batch xong), xem kết quả. 3. Chờ batch hoàn tất, xem lại. | Lượt chạy | Phạm vi thực hiện và đối chiếu | | --- | --- | | Run: Base | Toàn bộ thủ tục theo đúng thứ tự; các đối chứng cùng fixture được kiểm trong cùng lượt, không bỏ bước | | L20: 1. Ngay sau khi lưu: kết quả cũ vẫn hiện; không báo "hoàn tất" khi mới xếp hàng. 2. Sau batch thành công: kết quả theo M=50. | O20: 1 | P20: =IF(OR(COUNTIF('Run Log'!$B:$B,A20)<>O20,COUNTIF('Run Log'!$A:$A,"RUN-TC-RS-FUNC-020-Base")<>1,COUNTIFS('Run Log'!$A:$A,"RUN-TC-RS-FUNC-020-Base",'Run Log'!$B:$B,A20,'Run Log'!$C:$C,"Base")<>1),"INCOMPLETE",IF(COUNTIFS('Run Log'!$B:$B,A20,'Run Log'!$D:$D,"PASS")=O20,"PASS",IF(COUNTIFS('Run Log'!$B:$B,A20,'Run Log'!$D:$D,"FAIL")>0,"FAIL",IF(COUNTIFS('Run Log'!$B:$B,A20,'Run Log'!$D:$D,"BLOCKED")>0,"BLOCKED",IF(COUNTIFS('Run Log'!$B:$B,A20,'Run Log'!$D:$D,"SKIPPED")>0,"SKIPPED","NOT RUN")))))
A21: TC-RS-FUNC-021 | B21: Trường chỉ có quy tắc đỏ (không có tính tự động) vẫn có đường chạy hàng loạt | C21: A. Functional | D21: - Điều kiện: Trường không có quy tắc tính tự động nào đang hoạt động; mục số nguyên (M=100) có quy tắc “Cố định 30” (dưới 30). - Dữ liệu test: mục số nguyên (M=100); quy tắc “Cố định 30” (dưới 30), tài khoản có quyền chạy hàng loạt | E21: Cao | F21: CONFIRMED | G21: UNASSESSED | H21: tiêu chí nghiệm thu “Bao phủ đường đăng ký và chạy lại” (AC-G23 «Bao phủ đường đăng ký và chạy lại») | I21: A. Functional | J21: test-cases.vi.md | K21: 1. Mở Tổng hợp thành tích（成績集計） (`/admin/grade/grade_setting_system/grade_calc`). 2. Tìm thao tác Thực hiện tính toán tự động（自動算出実行） cho Khối 1, kỳ 1学期期末 (cuối kỳ học kỳ 1). 3. Chạy, chờ hoàn tất, xem kết quả. | Lượt chạy | Phạm vi thực hiện và đối chiếu | | --- | --- | | Run: Base | Toàn bộ thủ tục theo đúng thứ tự; các đối chứng cùng fixture được kiểm trong cùng lượt, không bỏ bước | | L21: Chạy được bằng thao tác hàng loạt hiện có (không có chế độ xét đỏ riêng); sau khi chạy, các ô được xét theo quy tắc “Cố định 30” (dưới 30). Nhãn/cách hiện nút cho trường không có tính tự động chưa chốt — không đánh giá phần này. | O21: 1 | P21: =IF(OR(COUNTIF('Run Log'!$B:$B,A21)<>O21,COUNTIF('Run Log'!$A:$A,"RUN-TC-RS-FUNC-021-Base")<>1,COUNTIFS('Run Log'!$A:$A,"RUN-TC-RS-FUNC-021-Base",'Run Log'!$B:$B,A21,'Run Log'!$C:$C,"Base")<>1),"INCOMPLETE",IF(COUNTIFS('Run Log'!$B:$B,A21,'Run Log'!$D:$D,"PASS")=O21,"PASS",IF(COUNTIFS('Run Log'!$B:$B,A21,'Run Log'!$D:$D,"FAIL")>0,"FAIL",IF(COUNTIFS('Run Log'!$B:$B,A21,'Run Log'!$D:$D,"BLOCKED")>0,"BLOCKED",IF(COUNTIFS('Run Log'!$B:$B,A21,'Run Log'!$D:$D,"SKIPPED")>0,"SKIPPED","NOT RUN")))))
A22: TC-RS-FUNC-022 | B22: Trích xuất thành tích（成績抽出）: các tùy chọn đỏ được lưu và mở lại đúng | C22: A. Functional | D22: - Điều kiện: mục số nguyên (M=100) có quy tắc “Cố định 30” (dưới 30). Đăng nhập tài khoản phụ trách đầu ra (trích xuất, công khai, phiếu điểm). - Dữ liệu test: mục số nguyên (M=100), quy tắc “Cố định 30” (dưới 30); cấu hình trích xuất: lọc, ký hiệu “*” phía trước, tô màu, cấu hình trích xuất chỉ ký hiệu (“※” trước, “!” sau) | E22: Cao | F22: CONFIRMED | G22: UNASSESSED | H22: tiêu chí nghiệm thu “Hiển thị ô trích xuất” (AC-G30 «Hiển thị ô trích xuất») | I22: A. Functional | J22: test-cases.vi.md | K22: 1. Mở thiết lập hiển thị của trích xuất, khung Thiết lập chi tiết thông tin lớp học（授業情報の詳細設定）, phần điều kiện đỏ. 2. Cấu hình cấu hình trích xuất: lọc, ký hiệu “*” phía trước, tô màu, lưu, mở lại. 3. Cấu hình cấu hình trích xuất chỉ ký hiệu (“※” trước, “!” sau) (hai ký hiệu cùng bật), lưu, mở lại. 4. (PROPOSED) Chạy SELECT cột `extract_setting` của dòng `grade_extract_conf` tương ứng mẫu vừa lưu, lọc theo trường/năm test. 5. (PROPOSED) Nếu màn có chức năng sao chép thiết lập trích xuất hiện có: sao chép mẫu cấu hình trích xuất: lọc, ký hiệu “*” phía trước, tô màu, mở bản sao. | Lượt chạy | Phạm vi thực hiện và đối chiếu | | --- | --- | | Run: filter-color | Cấu hình lọc và màu | | Run: prefix-suffix | Cấu hình ký hiệu trước/sau | | Run: copy | Sao chép cấu hình theo phần đề xuất | | L22: 1. Có bốn tùy chọn độc lập: lọc học sinh có điểm đỏ, ký hiệu phía trước, ký hiệu phía sau, tô màu ô. 2. Ký hiệu trước và sau cùng bật được. 3. Màu chỉ chọn từ bảng màu hiện có (không có bộ chọn màu tự do). 4. Mở lại giữ đúng giá trị. 5. (PROPOSED) JSON `extract_setting` chứa phần điều kiện đỏ với các khóa `use_target_extract`, `use_prefix_mark`, `prefix_mark`, `use_suffix_mark`, `suffix_mark`, `use_cell_coloring`, `cell_color` khớp giá trị trên màn; không có cột/bảng mới cho thiết lập này. 6. (PROPOSED) Bản sao giữ nguyên bốn tùy chọn, ký hiệu và màu. | O22: 3 | P22: =IF(OR(COUNTIF('Run Log'!$B:$B,A22)<>O22,COUNTIF('Run Log'!$A:$A,"RUN-TC-RS-FUNC-022-filter-color")<>1,COUNTIFS('Run Log'!$A:$A,"RUN-TC-RS-FUNC-022-filter-color",'Run Log'!$B:$B,A22,'Run Log'!$C:$C,"filter-color")<>1,COUNTIF('Run Log'!$A:$A,"RUN-TC-RS-FUNC-022-prefix-suffix")<>1,COUNTIFS('Run Log'!$A:$A,"RUN-TC-RS-FUNC-022-prefix-suffix",'Run Log'!$B:$B,A22,'Run Log'!$C:$C,"prefix-suffix")<>1,COUNTIF('Run Log'!$A:$A,"RUN-TC-RS-FUNC-022-copy")<>1,COUNTIFS('Run Log'!$A:$A,"RUN-TC-RS-FUNC-022-copy",'Run Log'!$B:$B,A22,'Run Log'!$C:$C,"copy")<>1),"INCOMPLETE",IF(COUNTIFS('Run Log'!$B:$B,A22,'Run Log'!$D:$D,"PASS")=O22,"PASS",IF(COUNTIFS('Run Log'!$B:$B,A22,'Run Log'!$D:$D,"FAIL")>0,"FAIL",IF(COUNTIFS('Run Log'!$B:$B,A22,'Run Log'!$D:$D,"BLOCKED")>0,"BLOCKED",IF(COUNTIFS('Run Log'!$B:$B,A22,'Run Log'!$D:$D,"SKIPPED")>0,"SKIPPED","NOT RUN")))))
A23: TC-RS-FUNC-023 | B23: Trích xuất: lọc giữ học sinh có ít nhất một ô đỏ trong phạm vi đang xét | C23: A. Functional | D23: - Điều kiện: Kết quả đã xét: S10 Toán 24 Đỏ và Ngữ văn 20 Đỏ trong cùng phạm vi; S03 Không đỏ ở mọi môn. S10 có thêm ô Toán ở một thời điểm khác, Không đỏ. S06 có mục điểm đơn vị (đơn vị U1 có M riêng 40) U1 = 25 Đỏ, U2 = 35 Không đỏ. - Dữ liệu test: học sinh S10 (học lớp G-B và G-C), học sinh S03 (điểm 31), học sinh S06 (điểm dự kiến 24), mục điểm đơn vị (đơn vị U1 có M riêng 40), quy tắc “Cố định 30” (dưới 30), cấu hình trích xuất: lọc, ký hiệu “*” phía trước, tô màu, cấu hình trích xuất chỉ ký hiệu (“※” trước, “!” sau) | E23: Cao | F23: CONFIRMED | G23: UNASSESSED | H23: tiêu chí nghiệm thu “Lọc khi trích xuất” (AC-G29 «Lọc khi trích xuất») | I23: A. Functional | J23: test-cases.vi.md | K23: 1. Chạy trích xuất với cấu hình trích xuất: lọc, ký hiệu “*” phía trước, tô màu, phạm vi gồm Toán và Ngữ văn. 2. Chạy lại với phạm vi chỉ Ngữ văn. 3. Chạy với cấu hình trích xuất chỉ ký hiệu (“※” trước, “!” sau) (lọc tắt). 4. Với cấu hình trích xuất: lọc, ký hiệu “*” phía trước, tô màu, chọn thời điểm khác thời điểm có ô Toán Đỏ của S10 (ô Toán của thời điểm đó Không đỏ). 5. Với cấu hình trích xuất: lọc, ký hiệu “*” phía trước, tô màu và mục điểm đơn vị (đơn vị U1 có M riêng 40): S06 có U1 Đỏ, U2 Không đỏ; chọn phạm vi chỉ U2. 6. Xóa thành công ô Toán của S10, chạy lại lọc với cả Toán và Ngữ văn. | Lượt chạy | Phạm vi thực hiện và đối chiếu | | --- | --- | | Run: multi-red-scope | Bước 1, S10 có hai ô đỏ trong phạm vi | | Run: one-red-in-scope | Bước 2, S10 chỉ còn Ngữ văn trong phạm vi | | Run: no-red-in-scope | Đối chứng S03 của bước 1, không ô nào đỏ | | Run: filter-off | Bước 3, chỉ ký hiệu và tắt lọc | | Run: another-period-only | Bước 4, ô đỏ nằm ở thời điểm khác | | Run: other-unit-only | Bước 5, chỉ U2 Không đỏ | | Run: after-delete | Bước 6 sau baseline bước 1, xóa Toán nhưng giữ Ngữ văn | | L23: 1. Bước 1: S10 có trong danh sách, S03 không. 2. Bước 2: S10 vẫn có trong danh sách nhờ Ngữ văn 20 Đỏ; không được loại S10 chỉ vì ô Toán ngoài phạm vi. 3. Bước 3: danh sách không bị lọc theo đỏ (chỉ bật ký hiệu không giới hạn học sinh). 4. Bước 4: S10 không có trong danh sách; ô đỏ ở thời điểm khác không giúp thỏa điều kiện. 5. Bước 5: S06 không có trong danh sách; ô đỏ của U1 ngoài phạm vi đơn vị. 6. S10 vẫn có trong danh sách nhờ Ngữ văn 20 Đỏ; ô Toán đã xóa không còn dấu đỏ. | O23: 7 | P23: =IF(OR(COUNTIF('Run Log'!$B:$B,A23)<>O23,COUNTIF('Run Log'!$A:$A,"RUN-TC-RS-FUNC-023-multi-red-scope")<>1,COUNTIFS('Run Log'!$A:$A,"RUN-TC-RS-FUNC-023-multi-red-scope",'Run Log'!$B:$B,A23,'Run Log'!$C:$C,"multi-red-scope")<>1,COUNTIF('Run Log'!$A:$A,"RUN-TC-RS-FUNC-023-one-red-in-scope")<>1,COUNTIFS('Run Log'!$A:$A,"RUN-TC-RS-FUNC-023-one-red-in-scope",'Run Log'!$B:$B,A23,'Run Log'!$C:$C,"one-red-in-scope")<>1,COUNTIF('Run Log'!$A:$A,"RUN-TC-RS-FUNC-023-no-red-in-scope")<>1,COUNTIFS('Run Log'!$A:$A,"RUN-TC-RS-FUNC-023-no-red-in-scope",'Run Log'!$B:$B,A23,'Run Log'!$C:$C,"no-red-in-scope")<>1,COUNTIF('Run Log'!$A:$A,"RUN-TC-RS-FUNC-023-filter-off")<>1,COUNTIFS('Run Log'!$A:$A,"RUN-TC-RS-FUNC-023-filter-off",'Run Log'!$B:$B,A23,'Run Log'!$C:$C,"filter-off")<>1,COUNTIF('Run Log'!$A:$A,"RUN-TC-RS-FUNC-023-another-period-only")<>1,COUNTIFS('Run Log'!$A:$A,"RUN-TC-RS-FUNC-023-another-period-only",'Run Log'!$B:$B,A23,'Run Log'!$C:$C,"another-period-only")<>1,COUNTIF('Run Log'!$A:$A,"RUN-TC-RS-FUNC-023-other-unit-only")<>1,COUNTIFS('Run Log'!$A:$A,"RUN-TC-RS-FUNC-023-other-unit-only",'Run Log'!$B:$B,A23,'Run Log'!$C:$C,"other-unit-only")<>1,COUNTIF('Run Log'!$A:$A,"RUN-TC-RS-FUNC-023-after-delete")<>1,COUNTIFS('Run Log'!$A:$A,"RUN-TC-RS-FUNC-023-after-delete",'Run Log'!$B:$B,A23,'Run Log'!$C:$C,"after-delete")<>1),"INCOMPLETE",IF(COUNTIFS('Run Log'!$B:$B,A23,'Run Log'!$D:$D,"PASS")=O23,"PASS",IF(COUNTIFS('Run Log'!$B:$B,A23,'Run Log'!$D:$D,"FAIL")>0,"FAIL",IF(COUNTIFS('Run Log'!$B:$B,A23,'Run Log'!$D:$D,"BLOCKED")>0,"BLOCKED",IF(COUNTIFS('Run Log'!$B:$B,A23,'Run Log'!$D:$D,"SKIPPED")>0,"SKIPPED","NOT RUN")))))
A24: TC-RS-FUNC-024 | B24: Trích xuất: chỉ ô đỏ được thêm ký hiệu/tô màu | C24: A. Functional | D24: - Điều kiện: fixture riêng S10, Toán=24 Đỏ và Ngữ văn=70 Không đỏ; ngưỡng cố định 30, dấu nhỏ hơn, M=100 ở cả hai mục. Không kế thừa Ngữ văn=20 của FUNC-023. - Dữ liệu test: học sinh S10 (học lớp G-B và G-C), cấu hình trích xuất: lọc, ký hiệu “*” phía trước, tô màu, cấu hình trích xuất chỉ ký hiệu (“※” trước, “!” sau) | E24: Cao | F24: CONFIRMED | G24: UNASSESSED | H24: tiêu chí nghiệm thu “Hiển thị ô trích xuất” (AC-G30 «Hiển thị ô trích xuất») | I24: A. Functional | J24: test-cases.vi.md | K24: 1. Chạy trích xuất cấu hình trích xuất: lọc, ký hiệu “*” phía trước, tô màu, xem dòng S10. 2. Chạy cấu hình trích xuất chỉ ký hiệu (“※” trước, “!” sau), xem dòng S10. | Lượt chạy | Phạm vi thực hiện và đối chiếu | | --- | --- | | Run: prefix-color | Ký hiệu trước và màu | | Run: prefix-suffix | Ký hiệu trước và sau | | L24: 1. cấu hình trích xuất: lọc, ký hiệu “*” phía trước, tô màu: ô Toán hiện `*24` với nền màu Đỏ（赤） của bảng màu; ô Ngữ văn `70` không ký hiệu, không màu; không tô cả dòng. 2. cấu hình trích xuất chỉ ký hiệu (“※” trước, “!” sau): ô Toán `※24!`; ô Ngữ văn `70`. | O24: 2 | P24: =IF(OR(COUNTIF('Run Log'!$B:$B,A24)<>O24,COUNTIF('Run Log'!$A:$A,"RUN-TC-RS-FUNC-024-prefix-color")<>1,COUNTIFS('Run Log'!$A:$A,"RUN-TC-RS-FUNC-024-prefix-color",'Run Log'!$B:$B,A24,'Run Log'!$C:$C,"prefix-color")<>1,COUNTIF('Run Log'!$A:$A,"RUN-TC-RS-FUNC-024-prefix-suffix")<>1,COUNTIFS('Run Log'!$A:$A,"RUN-TC-RS-FUNC-024-prefix-suffix",'Run Log'!$B:$B,A24,'Run Log'!$C:$C,"prefix-suffix")<>1),"INCOMPLETE",IF(COUNTIFS('Run Log'!$B:$B,A24,'Run Log'!$D:$D,"PASS")=O24,"PASS",IF(COUNTIFS('Run Log'!$B:$B,A24,'Run Log'!$D:$D,"FAIL")>0,"FAIL",IF(COUNTIFS('Run Log'!$B:$B,A24,'Run Log'!$D:$D,"BLOCKED")>0,"BLOCKED",IF(COUNTIFS('Run Log'!$B:$B,A24,'Run Log'!$D:$D,"SKIPPED")>0,"SKIPPED","NOT RUN")))))
A25: TC-RS-FUNC-025 | B25: Trích xuất: file Excel khớp màn hình | C25: A. Functional | D25: - Điều kiện: Như case “Trích xuất: chỉ ô đỏ được thêm ký hiệu/tô màu”; S05 có ô trống. - Dữ liệu test: cấu hình trích xuất: lọc, ký hiệu “*” phía trước, tô màu, cấu hình trích xuất chỉ ký hiệu (“※” trước, “!” sau), học sinh S05 (ô trống), học sinh S10 (học lớp G-B và G-C) | E25: Cao | F25: CONFIRMED | G25: UNASSESSED | H25: tiêu chí nghiệm thu “Excel khớp và dùng kết luận server” (AC-G31 «Excel khớp và dùng kết luận server») | I25: A. Functional | J25: test-cases.vi.md | K25: 1. Chạy trích xuất, chụp màn kết quả. 2. Xuất Excel, mở file. 3. Lặp bước 1–2 với: (a) cấu hình trích xuất chỉ ký hiệu (“※” trước, “!” sau) (lọc đỏ TẮT); (b) phạm vi không có ô đỏ nào (0 kết quả); (c) sau khi một ô Đỏ bị ngừng kết quả cũ (như case “Chưa có kết quả tổng hợp → Chưa xét được, không thay bằng 0 hay nhóm khác”, Chưa xét được); (d) mục có điểm bị ẩn theo thiết lập ẩn mục nhập (như case “Mục bị ẩn theo thiết lập ẩn mục nhập”). | Lượt chạy | Phạm vi thực hiện và đối chiếu | | --- | --- | | Run: filter-on | Lượt ban đầu bật lọc | | Run: filter-off | Nhánh a tắt lọc | | Run: empty | Nhánh b không có ô đỏ | | Run: stale | Nhánh c kết quả không còn hiệu lực | | Run: hidden | Nhánh d điểm ẩn | | L25: 1–2. Danh sách học sinh trong Excel giống màn hình (lọc đỏ đang bật). Cùng ô: ký hiệu, màu nền, số liệu, ô trống trong Excel giống màn hình. Ô trống không hiện số 0. Tải Excel không kích hoạt xét. 3. Mỗi biến thể: file Excel khớp màn hình cùng lần — (a) đủ học sinh, chỉ ô đỏ có ký hiệu/màu; (b) Excel không có học sinh giống màn hình; (c) ô bị ngừng kết quả cũ không còn ký hiệu/màu; (d) điểm ẩn không hiện lại trong Excel. | O25: 5 | P25: =IF(OR(COUNTIF('Run Log'!$B:$B,A25)<>O25,COUNTIF('Run Log'!$A:$A,"RUN-TC-RS-FUNC-025-filter-on")<>1,COUNTIFS('Run Log'!$A:$A,"RUN-TC-RS-FUNC-025-filter-on",'Run Log'!$B:$B,A25,'Run Log'!$C:$C,"filter-on")<>1,COUNTIF('Run Log'!$A:$A,"RUN-TC-RS-FUNC-025-filter-off")<>1,COUNTIFS('Run Log'!$A:$A,"RUN-TC-RS-FUNC-025-filter-off",'Run Log'!$B:$B,A25,'Run Log'!$C:$C,"filter-off")<>1,COUNTIF('Run Log'!$A:$A,"RUN-TC-RS-FUNC-025-empty")<>1,COUNTIFS('Run Log'!$A:$A,"RUN-TC-RS-FUNC-025-empty",'Run Log'!$B:$B,A25,'Run Log'!$C:$C,"empty")<>1,COUNTIF('Run Log'!$A:$A,"RUN-TC-RS-FUNC-025-stale")<>1,COUNTIFS('Run Log'!$A:$A,"RUN-TC-RS-FUNC-025-stale",'Run Log'!$B:$B,A25,'Run Log'!$C:$C,"stale")<>1,COUNTIF('Run Log'!$A:$A,"RUN-TC-RS-FUNC-025-hidden")<>1,COUNTIFS('Run Log'!$A:$A,"RUN-TC-RS-FUNC-025-hidden",'Run Log'!$B:$B,A25,'Run Log'!$C:$C,"hidden")<>1),"INCOMPLETE",IF(COUNTIFS('Run Log'!$B:$B,A25,'Run Log'!$D:$D,"PASS")=O25,"PASS",IF(COUNTIFS('Run Log'!$B:$B,A25,'Run Log'!$D:$D,"FAIL")>0,"FAIL",IF(COUNTIFS('Run Log'!$B:$B,A25,'Run Log'!$D:$D,"BLOCKED")>0,"BLOCKED",IF(COUNTIFS('Run Log'!$B:$B,A25,'Run Log'!$D:$D,"SKIPPED")>0,"SKIPPED","NOT RUN")))))
A26: TC-RS-FUNC-026 | B26: Công khai thành tích（成績公開）: ba hiệu ứng đỏ hiển thị đúng ở màn học sinh | C26: A. Functional | D26: - Điều kiện: S01 Đỏ (29), không phải điểm dự kiến. Lịch công khai đang mở. - Dữ liệu test: mục số nguyên (M=100); mục điểm đơn vị (đơn vị U1 có M riêng 40); học sinh S01 (điểm 29), học sinh S06 (điểm dự kiến 24), tài khoản học sinh S01, tài khoản phụ trách đầu ra (trích xuất, công khai, phiếu điểm) | E26: Cao | F26: CONFIRMED | G26: UNASSESSED | H26: tiêu chí nghiệm thu “Cấu hình công khai và ẩn điểm” (AC-G32 «Cấu hình công khai và ẩn điểm») | I26: A. Functional | J26: test-cases.vi.md | K26: 1. Ở Thiết lập công khai thành tích（成績公開設定）, mục mục số nguyên (M=100), chọn hiệu ứng đỏ Ngoặc（括弧）, lưu. Đăng nhập S01 xem Xác nhận thành tích（成績確認）. 2. Lặp với `*` phía trước. 3. Lặp với `*` phía sau. 4. Mở lại Thiết lập công khai thành tích. 5. Với mục điểm đơn vị mục điểm đơn vị (đơn vị U1 có M riêng 40) (S06 U1 = 25 Đỏ), chọn `*` phía trước, lưu; đăng nhập S06 xem. | Lượt chạy | Phạm vi thực hiện và đối chiếu | | --- | --- | | Run: parentheses | Hiệu ứng ngoặc | | Run: prefix | Hiệu ứng phía trước | | Run: suffix-reopen | Hiệu ứng phía sau và mở lại | | Run: unit-prefix | Điểm đơn vị với hiệu ứng phía trước | | L26: 1–3. Lần lượt `(29)`, `*29`, `29*`. Không có nền màu riêng cho ô đỏ. 4. Hiệu ứng đã lưu gần nhất (`*` phía sau) được chọn sẵn. 5. Ô U1 hiện `*25`; ô U2 không ký hiệu. | O26: 4 | P26: =IF(OR(COUNTIF('Run Log'!$B:$B,A26)<>O26,COUNTIF('Run Log'!$A:$A,"RUN-TC-RS-FUNC-026-parentheses")<>1,COUNTIFS('Run Log'!$A:$A,"RUN-TC-RS-FUNC-026-parentheses",'Run Log'!$B:$B,A26,'Run Log'!$C:$C,"parentheses")<>1,COUNTIF('Run Log'!$A:$A,"RUN-TC-RS-FUNC-026-prefix")<>1,COUNTIFS('Run Log'!$A:$A,"RUN-TC-RS-FUNC-026-prefix",'Run Log'!$B:$B,A26,'Run Log'!$C:$C,"prefix")<>1,COUNTIF('Run Log'!$A:$A,"RUN-TC-RS-FUNC-026-suffix-reopen")<>1,COUNTIFS('Run Log'!$A:$A,"RUN-TC-RS-FUNC-026-suffix-reopen",'Run Log'!$B:$B,A26,'Run Log'!$C:$C,"suffix-reopen")<>1,COUNTIF('Run Log'!$A:$A,"RUN-TC-RS-FUNC-026-unit-prefix")<>1,COUNTIFS('Run Log'!$A:$A,"RUN-TC-RS-FUNC-026-unit-prefix",'Run Log'!$B:$B,A26,'Run Log'!$C:$C,"unit-prefix")<>1),"INCOMPLETE",IF(COUNTIFS('Run Log'!$B:$B,A26,'Run Log'!$D:$D,"PASS")=O26,"PASS",IF(COUNTIFS('Run Log'!$B:$B,A26,'Run Log'!$D:$D,"FAIL")>0,"FAIL",IF(COUNTIFS('Run Log'!$B:$B,A26,'Run Log'!$D:$D,"BLOCKED")>0,"BLOCKED",IF(COUNTIFS('Run Log'!$B:$B,A26,'Run Log'!$D:$D,"SKIPPED")>0,"SKIPPED","NOT RUN")))))
A27: TC-RS-FUNC-027 | B27: Công khai: kết hợp hiệu ứng Điểm dự kiến（見込点） và điểm đỏ, khử trùng | C27: A. Functional | D27: - Điều kiện: S06 = 24, vừa là Điểm dự kiến（見込点） vừa Đỏ. - Dữ liệu test: học sinh S06 (điểm dự kiến 24), tài khoản học sinh S06; fixture quyền phải map đúng học sinh S06, không dùng tài khoản S01 để xem dữ liệu S06. | E27: Cao | F27: CONFIRMED | G27: UNASSESSED | H27: tiêu chí nghiệm thu “Kết hợp hiệu ứng công khai” (AC-G33 «Kết hợp hiệu ứng công khai») | I27: A. Functional | J27: test-cases.vi.md | K27: Với mỗi dòng của bảng dưới, cấu hình hiệu ứng dự kiến và hiệu ứng đỏ, lưu, xem màn học sinh của S06. (a) Ngoặc + `*` trước; (b) `*` trước + `*` trước; (c) Ngoặc + Ngoặc; (d) `*` trước + `*` sau; (e) không trang trí + Ngoặc; (f) điểm bị ẩn theo thiết lập hiện có（表示しない） + `*` trước. | Lượt chạy | Phạm vi thực hiện và đối chiếu | | --- | --- | | Run: a | Thực hiện tổ hợp (a) | | Run: b | Thực hiện tổ hợp (b) | | Run: c | Thực hiện tổ hợp (c) | | Run: d | Thực hiện tổ hợp (d) | | Run: e | Thực hiện tổ hợp (e) | | Run: f | Thực hiện tổ hợp (f) | | L27: (a) `(*24)`; (b) `*24`, không phải `**24`; (c) `(24)`, không phải `((24))`; (d) `*24*`; (e) `(24)`; (f) vẫn ẩn, không hiện số, không để lại riêng dấu `*`. | O27: 6 | P27: =IF(OR(COUNTIF('Run Log'!$B:$B,A27)<>O27,COUNTIF('Run Log'!$A:$A,"RUN-TC-RS-FUNC-027-a")<>1,COUNTIFS('Run Log'!$A:$A,"RUN-TC-RS-FUNC-027-a",'Run Log'!$B:$B,A27,'Run Log'!$C:$C,"a")<>1,COUNTIF('Run Log'!$A:$A,"RUN-TC-RS-FUNC-027-b")<>1,COUNTIFS('Run Log'!$A:$A,"RUN-TC-RS-FUNC-027-b",'Run Log'!$B:$B,A27,'Run Log'!$C:$C,"b")<>1,COUNTIF('Run Log'!$A:$A,"RUN-TC-RS-FUNC-027-c")<>1,COUNTIFS('Run Log'!$A:$A,"RUN-TC-RS-FUNC-027-c",'Run Log'!$B:$B,A27,'Run Log'!$C:$C,"c")<>1,COUNTIF('Run Log'!$A:$A,"RUN-TC-RS-FUNC-027-d")<>1,COUNTIFS('Run Log'!$A:$A,"RUN-TC-RS-FUNC-027-d",'Run Log'!$B:$B,A27,'Run Log'!$C:$C,"d")<>1,COUNTIF('Run Log'!$A:$A,"RUN-TC-RS-FUNC-027-e")<>1,COUNTIFS('Run Log'!$A:$A,"RUN-TC-RS-FUNC-027-e",'Run Log'!$B:$B,A27,'Run Log'!$C:$C,"e")<>1,COUNTIF('Run Log'!$A:$A,"RUN-TC-RS-FUNC-027-f")<>1,COUNTIFS('Run Log'!$A:$A,"RUN-TC-RS-FUNC-027-f",'Run Log'!$B:$B,A27,'Run Log'!$C:$C,"f")<>1),"INCOMPLETE",IF(COUNTIFS('Run Log'!$B:$B,A27,'Run Log'!$D:$D,"PASS")=O27,"PASS",IF(COUNTIFS('Run Log'!$B:$B,A27,'Run Log'!$D:$D,"FAIL")>0,"FAIL",IF(COUNTIFS('Run Log'!$B:$B,A27,'Run Log'!$D:$D,"BLOCKED")>0,"BLOCKED",IF(COUNTIFS('Run Log'!$B:$B,A27,'Run Log'!$D:$D,"SKIPPED")>0,"SKIPPED","NOT RUN")))))
