Workbook

Sheet Tổng quan
A1: Báo cáo kiểm thử
A3: Nhập lần kiểm thử, phiên bản ứng dụng, môi trường, người và thời điểm thực hiện.
A4: Chức năng | B4: RC-001 — Điểm đỏ（赤点）
A5: Phiên bản kiểm thử | B5: RC-001-v2-report-2026-10-04
A6: Lần kiểm thử
A7: Phiên bản ứng dụng
A8: Môi trường
A9: Người thực hiện
A10: Thời điểm thực hiện (kèm múi giờ)
A11: Phạm vi | B11: 216 case và 569 biến thể: cấu hình quy tắc; nguồn/ngưỡng; xét và vòng đời kết quả; trích xuất, công khai, phiếu điểm; quyền và bảo toàn legacy. Chuẩn bị: Chuẩn bị và đọc lại đúng vai trò/quyền, lớp, mục, kỳ, nguồn và baseline của từng case. Ưu tiên UI hiện hữu; đường thực hiện chưa xác minh giữ Đang chuẩn bị/Bị chặn. Mỗi biến thể có trạng thái cần khôi phục dữ liệu đầu vào riêng. Điều kiện bắt đầu: Đã xác định phiên bản ứng dụng, quyền ghi ở môi trường kiểm thử, dữ liệu kiểm thử, đường kích hoạt và nơi quan sát của lượt được chọn; chọn đúng lát cắt phát hành trước khi chạy. Điều kiện kết thúc: Ghi kết quả thực tế, trạng thái, bằng chứng và lý do cho mọi lượt được chọn; chưa chuẩn bị/chưa chốt căn cứ kỳ vọng không được kết luận Đạt. Hoàn tất toàn bộ cần xác nhận đóng lượt và quyền xem bằng chứng thực tế.
A12: Ngoài phạm vi | B12: Xét trực tiếp mục A/B/C hoặc đạt/không đạt; công thức tự do; chuyển legacy thành rule mới; triển khai hoặc phát hành ứng dụng.
A13: Giới hạn | B13: Báo cáo mới chưa thực thi. Dữ liệu kiểm thử, đường thực hiện và phạm vi phát hành chưa xác minh vẫn Đang chuẩn bị/Bị chặn; không coi file có format đúng là QA hoàn tất. 23 khoảng trống được giữ trong điều kiện của các testcase tương ứng; xem Chi tiết khi có liên kết.
A14: Chuẩn bị theo testcase | B14: Sẵn sàng: 1 · Đang chuẩn bị: 198 · Bị chặn: 17 Tính theo testcase, độc lập với trạng thái đã chạy. Một testcase có thể có nhiều biến thể; mỗi dòng Kiểm thử là một biến thể.
A15: Tiến độ và kết quả
A16: Số testcase (trường hợp kiểm thử) | B16: =COUNTA(A30:A245)
A17: Số biến thể (dòng Kiểm thử) | B17: =COUNTA('Kiểm thử'!$A$5:$A$573)
A18: Phán định Đạt đủ điều kiện | B18: =SUMPRODUCT(--(('Kiểm thử'!$A$5:$A$573="TC-RS-REG-008 / web-open")+('Kiểm thử'!$A$5:$A$573="TC-RS-REG-008 / api-open")+('Kiểm thử'!$A$5:$A$573="TC-RS-REG-008 / pdf-open")+('Kiểm thử'!$A$5:$A$573="TC-RS-REG-008 / web-closed")+('Kiểm thử'!$A$5:$A$573="TC-RS-REG-008 / api-closed")+('Kiểm thử'!$A$5:$A$573="TC-RS-REG-008 / pdf-closed")),--EXACT('Kiểm thử'!$F$5:$F$573,"Đạt"),--(LEN(SUBSTITUTE(SUBSTITUTE(SUBSTITUTE(SUBSTITUTE(SUBSTITUTE(SUBSTITUTE(SUBSTITUTE(SUBSTITUTE(SUBSTITUTE(SUBSTITUTE(SUBSTITUTE(SUBSTITUTE(SUBSTITUTE(SUBSTITUTE(SUBSTITUTE(SUBSTITUTE(SUBSTITUTE(SUBSTITUTE(SUBSTITUTE(SUBSTITUTE(CLEAN('Kiểm thử'!$E$5:$E$573)," ","")," ","")," ","")," ","")," ","")," ","")," ","")," ","")," ","")," ","")," ","")," ","")," ","")," ","")," ","")," ","")," ","")," ","")," ","")," ",""))>0),--EXACT(LEFT(LEFT('Kiểm thử'!$G$5:$G$573,FIND(CHAR(10),'Kiểm thử'!$G$5:$G$573&CHAR(10))-1),8),"https://"),--(LEN(SUBSTITUTE(SUBSTITUTE(SUBSTITUTE(SUBSTITUTE(SUBSTITUTE(SUBSTITUTE(SUBSTITUTE(SUBSTITUTE(SUBSTITUTE(SUBSTITUTE(SUBSTITUTE(SUBSTITUTE(SUBSTITUTE(SUBSTITUTE(SUBSTITUTE(SUBSTITUTE(SUBSTITUTE(SUBSTITUTE(SUBSTITUTE(SUBSTITUTE(CLEAN(LEFT('Kiểm thử'!$G$5:$G$573,FIND(CHAR(10),'Kiểm thử'!$G$5:$G$573&CHAR(10))-1))," ","")," ","")," ","")," ","")," ","")," ","")," ","")," ","")," ","")," ","")," ","")," ","")," ","")," ","")," ","")," ","")," ","")," ","")," ","")," ",""))=LEN(LEFT('Kiểm thử'!$G$5:$G$573,FIND(CHAR(10),'Kiểm thử'!$G$5:$G$573&CHAR(10))-1))),--ISNUMBER(SEARCH("?*.?*",MID(SUBSTITUTE(SUBSTITUTE(LEFT('Kiểm thử'!$G$5:$G$573,FIND(CHAR(10),'Kiểm thử'!$G$5:$G$573&CHAR(10))-1),"?","/"),"#","/"),9,FIND("/",SUBSTITUTE(SUBSTITUTE(LEFT('Kiểm thử'!$G$5:$G$573,FIND(CHAR(10),'Kiểm thử'!$G$5:$G$573&CHAR(10))-1),"?","/"),"#","/")&"/////////",9)-9))),--ISERROR(SEARCH("@",MID(SUBSTITUTE(SUBSTITUTE(LEFT('Kiểm thử'!$G$5:$G$573,FIND(CHAR(10),'Kiểm thử'!$G$5:$G$573&CHAR(10))-1),"?","/"),"#","/"),9,FIND("/",SUBSTITUTE(SUBSTITUTE(LEFT('Kiểm thử'!$G$5:$G$573,FIND(CHAR(10),'Kiểm thử'!$G$5:$G$573&CHAR(10))-1),"?","/"),"#","/")&"/////////",9)-9))))
A19: Phán định Không đạt đủ điều kiện | B19: =SUMPRODUCT(--(('Kiểm thử'!$A$5:$A$573="TC-RS-REG-008 / web-open")+('Kiểm thử'!$A$5:$A$573="TC-RS-REG-008 / api-open")+('Kiểm thử'!$A$5:$A$573="TC-RS-REG-008 / pdf-open")+('Kiểm thử'!$A$5:$A$573="TC-RS-REG-008 / web-closed")+('Kiểm thử'!$A$5:$A$573="TC-RS-REG-008 / api-closed")+('Kiểm thử'!$A$5:$A$573="TC-RS-REG-008 / pdf-closed")),--EXACT('Kiểm thử'!$F$5:$F$573,"Không đạt"),--(LEN(SUBSTITUTE(SUBSTITUTE(SUBSTITUTE(SUBSTITUTE(SUBSTITUTE(SUBSTITUTE(SUBSTITUTE(SUBSTITUTE(SUBSTITUTE(SUBSTITUTE(SUBSTITUTE(SUBSTITUTE(SUBSTITUTE(SUBSTITUTE(SUBSTITUTE(SUBSTITUTE(SUBSTITUTE(SUBSTITUTE(SUBSTITUTE(SUBSTITUTE(CLEAN('Kiểm thử'!$E$5:$E$573)," ","")," ","")," ","")," ","")," ","")," ","")," ","")," ","")," ","")," ","")," ","")," ","")," ","")," ","")," ","")," ","")," ","")," ","")," ","")," ",""))>0),--EXACT(LEFT(LEFT('Kiểm thử'!$G$5:$G$573,FIND(CHAR(10),'Kiểm thử'!$G$5:$G$573&CHAR(10))-1),8),"https://"),--(LEN(SUBSTITUTE(SUBSTITUTE(SUBSTITUTE(SUBSTITUTE(SUBSTITUTE(SUBSTITUTE(SUBSTITUTE(SUBSTITUTE(SUBSTITUTE(SUBSTITUTE(SUBSTITUTE(SUBSTITUTE(SUBSTITUTE(SUBSTITUTE(SUBSTITUTE(SUBSTITUTE(SUBSTITUTE(SUBSTITUTE(SUBSTITUTE(SUBSTITUTE(CLEAN(LEFT('Kiểm thử'!$G$5:$G$573,FIND(CHAR(10),'Kiểm thử'!$G$5:$G$573&CHAR(10))-1))," ","")," ","")," ","")," ","")," ","")," ","")," ","")," ","")," ","")," ","")," ","")," ","")," ","")," ","")," ","")," ","")," ","")," ","")," ","")," ",""))=LEN(LEFT('Kiểm thử'!$G$5:$G$573,FIND(CHAR(10),'Kiểm thử'!$G$5:$G$573&CHAR(10))-1))),--ISNUMBER(SEARCH("?*.?*",MID(SUBSTITUTE(SUBSTITUTE(LEFT('Kiểm thử'!$G$5:$G$573,FIND(CHAR(10),'Kiểm thử'!$G$5:$G$573&CHAR(10))-1),"?","/"),"#","/"),9,FIND("/",SUBSTITUTE(SUBSTITUTE(LEFT('Kiểm thử'!$G$5:$G$573,FIND(CHAR(10),'Kiểm thử'!$G$5:$G$573&CHAR(10))-1),"?","/"),"#","/")&"/////////",9)-9))),--ISERROR(SEARCH("@",MID(SUBSTITUTE(SUBSTITUTE(LEFT('Kiểm thử'!$G$5:$G$573,FIND(CHAR(10),'Kiểm thử'!$G$5:$G$573&CHAR(10))-1),"?","/"),"#","/"),9,FIND("/",SUBSTITUTE(SUBSTITUTE(LEFT('Kiểm thử'!$G$5:$G$573,FIND(CHAR(10),'Kiểm thử'!$G$5:$G$573&CHAR(10))-1),"?","/"),"#","/")&"/////////",9)-9))))
A20: Kịch bản bị chặn | B20: =SUMPRODUCT(--EXACT('Kiểm thử'!$F$5:$F$573,"Bị chặn"))
A21: Kịch bản không thực hiện | B21: =SUMPRODUCT(--EXACT('Kiểm thử'!$F$5:$F$573,"Không thực hiện"))
A22: Kịch bản chưa thực hiện | B22: =SUMPRODUCT(--EXACT('Kiểm thử'!$F$5:$F$573,"Chưa thực hiện"))
A23: Phán định Đạt/Không đạt đủ điều kiện | B23: =B18+B19
A24: Tỷ lệ Đạt / phán định đủ điều kiện | B24: =IF(B23=0,"Chưa có dữ liệu",B18/B23)
A25: Phán định đủ điều kiện / toàn bộ kịch bản | B25: =IF(B17=0,"Chưa có dữ liệu",B23/B17)
A26: Kịch bản chưa đạt | B26: =B17-B18
A27: Trạng thái không hợp lệ | B27: =B17-SUM(SUMPRODUCT(--EXACT('Kiểm thử'!$F$5:$F$573,"Đạt")),SUMPRODUCT(--EXACT('Kiểm thử'!$F$5:$F$573,"Không đạt")),SUMPRODUCT(--EXACT('Kiểm thử'!$F$5:$F$573,"Bị chặn")),SUMPRODUCT(--EXACT('Kiểm thử'!$F$5:$F$573,"Không thực hiện")),SUMPRODUCT(--EXACT('Kiểm thử'!$F$5:$F$573,"Chưa thực hiện")))
A29: Mã kiểm thử | B29: Trạng thái
A30: TC-RS-FUNC-001 | B30: =IF(0>0,"Không đạt",IF(0=3,"Đạt",IF(SUMPRODUCT(--(('Kiểm thử'!$A$5:$A$573="TC-RS-FUNC-001 / integer")+('Kiểm thử'!$A$5:$A$573="TC-RS-FUNC-001 / decimal")+('Kiểm thử'!$A$5:$A$573="TC-RS-FUNC-001 / unit")),--EXACT('Kiểm thử'!$F$5:$F$573,"Không thực hiện"))=3,"Không thực hiện",IF(SUMPRODUCT(--(('Kiểm thử'!$A$5:$A$573="TC-RS-FUNC-001 / integer")+('Kiểm thử'!$A$5:$A$573="TC-RS-FUNC-001 / decimal")+('Kiểm thử'!$A$5:$A$573="TC-RS-FUNC-001 / unit")),--EXACT('Kiểm thử'!$F$5:$F$573,"Bị chặn"))>0,"Bị chặn",IF(SUMPRODUCT(--(('Kiểm thử'!$A$5:$A$573="TC-RS-FUNC-001 / integer")+('Kiểm thử'!$A$5:$A$573="TC-RS-FUNC-001 / decimal")+('Kiểm thử'!$A$5:$A$573="TC-RS-FUNC-001 / unit")),--EXACT('Kiểm thử'!$F$5:$F$573,"Chưa thực hiện"))=3,"Chưa thực hiện","Chưa đủ kết luận")))))
A31: TC-RS-FUNC-002 | B31: =IF(0>0,"Không đạt",IF(0=2,"Đạt",IF(SUMPRODUCT(--(('Kiểm thử'!$A$5:$A$573="TC-RS-FUNC-002 / choice")+('Kiểm thử'!$A$5:$A$573="TC-RS-FUNC-002 / passfail")),--EXACT('Kiểm thử'!$F$5:$F$573,"Không thực hiện"))=2,"Không thực hiện",IF(SUMPRODUCT(--(('Kiểm thử'!$A$5:$A$573="TC-RS-FUNC-002 / choice")+('Kiểm thử'!$A$5:$A$573="TC-RS-FUNC-002 / passfail")),--EXACT('Kiểm thử'!$F$5:$F$573,"Bị chặn"))>0,"Bị chặn",IF(SUMPRODUCT(--(('Kiểm thử'!$A$5:$A$573="TC-RS-FUNC-002 / choice")+('Kiểm thử'!$A$5:$A$573="TC-RS-FUNC-002 / passfail")),--EXACT('Kiểm thử'!$F$5:$F$573,"Chưa thực hiện"))=2,"Chưa thực hiện","Chưa đủ kết luận")))))
A32: TC-RS-FUNC-004 | B32: =IF(0>0,"Không đạt",IF(0=1,"Đạt",IF(SUMPRODUCT(--(('Kiểm thử'!$A$5:$A$573="TC-RS-FUNC-004 / Base")),--EXACT('Kiểm thử'!$F$5:$F$573,"Không thực hiện"))=1,"Không thực hiện",IF(SUMPRODUCT(--(('Kiểm thử'!$A$5:$A$573="TC-RS-FUNC-004 / Base")),--EXACT('Kiểm thử'!$F$5:$F$573,"Bị chặn"))>0,"Bị chặn",IF(SUMPRODUCT(--(('Kiểm thử'!$A$5:$A$573="TC-RS-FUNC-004 / Base")),--EXACT('Kiểm thử'!$F$5:$F$573,"Chưa thực hiện"))=1,"Chưa thực hiện","Chưa đủ kết luận")))))
A33: TC-RS-FUNC-005 | B33: =IF(0>0,"Không đạt",IF(0=1,"Đạt",IF(SUMPRODUCT(--(('Kiểm thử'!$A$5:$A$573="TC-RS-FUNC-005 / Base")),--EXACT('Kiểm thử'!$F$5:$F$573,"Không thực hiện"))=1,"Không thực hiện",IF(SUMPRODUCT(--(('Kiểm thử'!$A$5:$A$573="TC-RS-FUNC-005 / Base")),--EXACT('Kiểm thử'!$F$5:$F$573,"Bị chặn"))>0,"Bị chặn",IF(SUMPRODUCT(--(('Kiểm thử'!$A$5:$A$573="TC-RS-FUNC-005 / Base")),--EXACT('Kiểm thử'!$F$5:$F$573,"Chưa thực hiện"))=1,"Chưa thực hiện","Chưa đủ kết luận")))))
A34: TC-RS-FUNC-006 | B34: =IF(0>0,"Không đạt",IF(0=2,"Đạt",IF(SUMPRODUCT(--(('Kiểm thử'!$A$5:$A$573="TC-RS-FUNC-006 / cancel")+('Kiểm thử'!$A$5:$A$573="TC-RS-FUNC-006 / delete")),--EXACT('Kiểm thử'!$F$5:$F$573,"Không thực hiện"))=2,"Không thực hiện",IF(SUMPRODUCT(--(('Kiểm thử'!$A$5:$A$573="TC-RS-FUNC-006 / cancel")+('Kiểm thử'!$A$5:$A$573="TC-RS-FUNC-006 / delete")),--EXACT('Kiểm thử'!$F$5:$F$573,"Bị chặn"))>0,"Bị chặn",IF(SUMPRODUCT(--(('Kiểm thử'!$A$5:$A$573="TC-RS-FUNC-006 / cancel")+('Kiểm thử'!$A$5:$A$573="TC-RS-FUNC-006 / delete")),--EXACT('Kiểm thử'!$F$5:$F$573,"Chưa thực hiện"))=2,"Chưa thực hiện","Chưa đủ kết luận")))))
A35: TC-RS-FUNC-007 | B35: =IF(0>0,"Không đạt",IF(0=2,"Đạt",IF(SUMPRODUCT(--(('Kiểm thử'!$A$5:$A$573="TC-RS-FUNC-007 / back-threshold")+('Kiểm thử'!$A$5:$A$573="TC-RS-FUNC-007 / back-condition")),--EXACT('Kiểm thử'!$F$5:$F$573,"Không thực hiện"))=2,"Không thực hiện",IF(SUMPRODUCT(--(('Kiểm thử'!$A$5:$A$573="TC-RS-FUNC-007 / back-threshold")+('Kiểm thử'!$A$5:$A$573="TC-RS-FUNC-007 / back-condition")),--EXACT('Kiểm thử'!$F$5:$F$573,"Bị chặn"))>0,"Bị chặn",IF(SUMPRODUCT(--(('Kiểm thử'!$A$5:$A$573="TC-RS-FUNC-007 / back-threshold")+('Kiểm thử'!$A$5:$A$573="TC-RS-FUNC-007 / back-condition")),--EXACT('Kiểm thử'!$F$5:$F$573,"Chưa thực hiện"))=2,"Chưa thực hiện","Chưa đủ kết luận")))))
A36: TC-RS-FUNC-014 | B36: =IF(0>0,"Không đạt",IF(0=3,"Đạt",IF(SUMPRODUCT(--(('Kiểm thử'!$A$5:$A$573="TC-RS-FUNC-014 / incomplete-excluded")+('Kiểm thử'!$A$5:$A$573="TC-RS-FUNC-014 / complete-deleted-stale")+('Kiểm thử'!$A$5:$A$573="TC-RS-FUNC-014 / incomplete-deleted-stale")),--EXACT('Kiểm thử'!$F$5:$F$573,"Không thực hiện"))=3,"Không thực hiện",IF(SUMPRODUCT(--(('Kiểm thử'!$A$5:$A$573="TC-RS-FUNC-014 / incomplete-excluded")+('Kiểm thử'!$A$5:$A$573="TC-RS-FUNC-014 / complete-deleted-stale")+('Kiểm thử'!$A$5:$A$573="TC-RS-FUNC-014 / incomplete-deleted-stale")),--EXACT('Kiểm thử'!$F$5:$F$573,"Bị chặn"))>0,"Bị chặn",IF(SUMPRODUCT(--(('Kiểm thử'!$A$5:$A$573="TC-RS-FUNC-014 / incomplete-excluded")+('Kiểm thử'!$A$5:$A$573="TC-RS-FUNC-014 / complete-deleted-stale")+('Kiểm thử'!$A$5:$A$573="TC-RS-FUNC-014 / incomplete-deleted-stale")),--EXACT('Kiểm thử'!$F$5:$F$573,"Chưa thực hiện"))=3,"Chưa thực hiện","Chưa đủ kết luận")))))
A37: TC-RS-FUNC-033 | B37: =IF(0>0,"Không đạt",IF(0=1,"Đạt",IF(SUMPRODUCT(--(('Kiểm thử'!$A$5:$A$573="TC-RS-FUNC-033 / Base")),--EXACT('Kiểm thử'!$F$5:$F$573,"Không thực hiện"))=1,"Không thực hiện",IF(SUMPRODUCT(--(('Kiểm thử'!$A$5:$A$573="TC-RS-FUNC-033 / Base")),--EXACT('Kiểm thử'!$F$5:$F$573,"Bị chặn"))>0,"Bị chặn",IF(SUMPRODUCT(--(('Kiểm thử'!$A$5:$A$573="TC-RS-FUNC-033 / Base")),--EXACT('Kiểm thử'!$F$5:$F$573,"Chưa thực hiện"))=1,"Chưa thực hiện","Chưa đủ kết luận")))))
A38: TC-RS-VAL-014 | B38: =IF(0>0,"Không đạt",IF(0=6,"Đạt",IF(SUMPRODUCT(--(('Kiểm thử'!$A$5:$A$573="TC-RS-VAL-014 / empty")+('Kiểm thử'!$A$5:$A$573="TC-RS-VAL-014 / space")+('Kiểm thử'!$A$5:$A$573="TC-RS-VAL-014 / len255")+('Kiểm thử'!$A$5:$A$573="TC-RS-VAL-014 / len256")+('Kiểm thử'!$A$5:$A$573="TC-RS-VAL-014 / padded255")+('Kiểm thử'!$A$5:$A$573="TC-RS-VAL-014 / duplicate")),--EXACT('Kiểm thử'!$F$5:$F$573,"Không thực hiện"))=6,"Không thực hiện",IF(SUMPRODUCT(--(('Kiểm thử'!$A$5:$A$573="TC-RS-VAL-014 / empty")+('Kiểm thử'!$A$5:$A$573="TC-RS-VAL-014 / space")+('Kiểm thử'!$A$5:$A$573="TC-RS-VAL-014 / len255")+('Kiểm thử'!$A$5:$A$573="TC-RS-VAL-014 / len256")+('Kiểm thử'!$A$5:$A$573="TC-RS-VAL-014 / padded255")+('Kiểm thử'!$A$5:$A$573="TC-RS-VAL-014 / duplicate")),--EXACT('Kiểm thử'!$F$5:$F$573,"Bị chặn"))>0,"Bị chặn",IF(SUMPRODUCT(--(('Kiểm thử'!$A$5:$A$573="TC-RS-VAL-014 / empty")+('Kiểm thử'!$A$5:$A$573="TC-RS-VAL-014 / space")+('Kiểm thử'!$A$5:$A$573="TC-RS-VAL-014 / len255")+('Kiểm thử'!$A$5:$A$573="TC-RS-VAL-014 / len256")+('Kiểm thử'!$A$5:$A$573="TC-RS-VAL-014 / padded255")+('Kiểm thử'!$A$5:$A$573="TC-RS-VAL-014 / duplicate")),--EXACT('Kiểm thử'!$F$5:$F$573,"Chưa thực hiện"))=6,"Chưa thực hiện","Chưa đủ kết luận")))))
A39: TC-RS-VAL-016 | B39: =IF(0>0,"Không đạt",IF(0=1,"Đạt",IF(SUMPRODUCT(--(('Kiểm thử'!$A$5:$A$573="TC-RS-VAL-016 / Base")),--EXACT('Kiểm thử'!$F$5:$F$573,"Không thực hiện"))=1,"Không thực hiện",IF(SUMPRODUCT(--(('Kiểm thử'!$A$5:$A$573="TC-RS-VAL-016 / Base")),--EXACT('Kiểm thử'!$F$5:$F$573,"Bị chặn"))>0,"Bị chặn",IF(SUMPRODUCT(--(('Kiểm thử'!$A$5:$A$573="TC-RS-VAL-016 / Base")),--EXACT('Kiểm thử'!$F$5:$F$573,"Chưa thực hiện"))=1,"Chưa thực hiện","Chưa đủ kết luận")))))
A40: TC-RS-DATA-001 | B40: =IF(0>0,"Không đạt",IF(0=4,"Đạt",IF(SUMPRODUCT(--(('Kiểm thử'!$A$5:$A$573="TC-RS-DATA-001 / fixed")+('Kiểm thử'!$A$5:$A$573="TC-RS-DATA-001 / ratio")+('Kiểm thử'!$A$5:$A$573="TC-RS-DATA-001 / formula")+('Kiểm thử'!$A$5:$A$573="TC-RS-DATA-001 / filter")),--EXACT('Kiểm thử'!$F$5:$F$573,"Không thực hiện"))=4,"Không thực hiện",IF(SUMPRODUCT(--(('Kiểm thử'!$A$5:$A$573="TC-RS-DATA-001 / fixed")+('Kiểm thử'!$A$5:$A$573="TC-RS-DATA-001 / ratio")+('Kiểm thử'!$A$5:$A$573="TC-RS-DATA-001 / formula")+('Kiểm thử'!$A$5:$A$573="TC-RS-DATA-001 / filter")),--EXACT('Kiểm thử'!$F$5:$F$573,"Bị chặn"))>0,"Bị chặn",IF(SUMPRODUCT(--(('Kiểm thử'!$A$5:$A$573="TC-RS-DATA-001 / fixed")+('Kiểm thử'!$A$5:$A$573="TC-RS-DATA-001 / ratio")+('Kiểm thử'!$A$5:$A$573="TC-RS-DATA-001 / formula")+('Kiểm thử'!$A$5:$A$573="TC-RS-DATA-001 / filter")),--EXACT('Kiểm thử'!$F$5:$F$573,"Chưa thực hiện"))=4,"Chưa thực hiện","Chưa đủ kết luận")))))
A41: TC-RS-DATA-004 | B41: =IF(0>0,"Không đạt",IF(0=1,"Đạt",IF(SUMPRODUCT(--(('Kiểm thử'!$A$5:$A$573="TC-RS-DATA-004 / Base")),--EXACT('Kiểm thử'!$F$5:$F$573,"Không thực hiện"))=1,"Không thực hiện",IF(SUMPRODUCT(--(('Kiểm thử'!$A$5:$A$573="TC-RS-DATA-004 / Base")),--EXACT('Kiểm thử'!$F$5:$F$573,"Bị chặn"))>0,"Bị chặn",IF(SUMPRODUCT(--(('Kiểm thử'!$A$5:$A$573="TC-RS-DATA-004 / Base")),--EXACT('Kiểm thử'!$F$5:$F$573,"Chưa thực hiện"))=1,"Chưa thực hiện","Chưa đủ kết luận")))))
A42: TC-RS-UI-001 | B42: =IF(0>0,"Không đạt",IF(0=1,"Đạt",IF(SUMPRODUCT(--(('Kiểm thử'!$A$5:$A$573="TC-RS-UI-001 / Base")),--EXACT('Kiểm thử'!$F$5:$F$573,"Không thực hiện"))=1,"Không thực hiện",IF(SUMPRODUCT(--(('Kiểm thử'!$A$5:$A$573="TC-RS-UI-001 / Base")),--EXACT('Kiểm thử'!$F$5:$F$573,"Bị chặn"))>0,"Bị chặn",IF(SUMPRODUCT(--(('Kiểm thử'!$A$5:$A$573="TC-RS-UI-001 / Base")),--EXACT('Kiểm thử'!$F$5:$F$573,"Chưa thực hiện"))=1,"Chưa thực hiện","Chưa đủ kết luận")))))
...

Sheet Kiểm thử
A1: Kiểm thử
A3: Nhập kết quả thực tế và trạng thái; dòng đầu ô Bằng chứng / lỗi ghi URL HTTPS, các dòng sau ghi lý do và bước tiếp theo khi chưa đạt. Mục ngoài phạm vi chọn Không thực hiện; chỉ phán định Đạt/Không đạt có kỳ vọng đã xác nhận, điều kiện sẵn sàng và dữ liệu nhập đủ mới được tính. Phần trích chỉ để đọc lướt; mở ô có Xem chi tiết để đọc đầy đủ trước khi chạy.
A4: Mã kiểm thử | B4: Màn hình / chức năng | C4: Điều kiện / thao tác | D4: Kết quả mong đợi | E4: Kết quả thực tế | F4: Trạng thái | G4: Bằng chứng / lỗi
A5: TC-RS-FUNC-001 / integer | B5: Thiết lập điểm đỏ（赤点設定） Hàng Thiết lập điểm đỏ（赤点設定） xuất hiện trong Thiết lập ô nhập（入力欄設定） cho mục… Xem chi tiết | C5: Chuẩn bị: Đang chuẩn bị Kỳ vọng: Đề xuất Dữ liệu (trích): Mục số nguyên Thao tác (trích): 1. Mở Thiết lập nhập điểm（成績入力設定）→ Thiết lập ô nhập（入力欄設定） của kỳ 1学期期末 (cuối kỳ học kỳ 1).… Xem chi tiết | D5: Kỳ vọng: Đề xuất 1. Theo Figma MW, hàng Thiết lập điểm đỏ（赤点設定） được đặt giữa hàng Tính tự động（自動計算） và hàng Thiết lập ẩn mục nhập（入力項目の非表示設定）. Đây là oracle UI PROPOSED; nếu bố cục khác, ghi… Xem chi tiết | F5: Chưa thực hiện
A6: TC-RS-FUNC-001 / decimal | B6: Thiết lập điểm đỏ（赤点設定） Hàng Thiết lập điểm đỏ（赤点設定） xuất hiện trong Thiết lập ô nhập（入力欄設定） cho mục… Xem chi tiết | C6: Chuẩn bị: Đang chuẩn bị Kỳ vọng: Đề xuất Dữ liệu (trích): Mục thập phân Thao tác (trích): 1. Mở Thiết lập nhập điểm（成績入力設定）→ Thiết lập ô nhập（入力欄設定） của kỳ 1学期期末 (cuối kỳ học kỳ 1).… Xem chi tiết | D6: Kỳ vọng: Đề xuất 1. Theo Figma MW, hàng Thiết lập điểm đỏ（赤点設定） được đặt giữa hàng Tính tự động（自動計算） và hàng Thiết lập ẩn mục nhập（入力項目の非表示設定）. Đây là oracle UI PROPOSED; nếu bố cục khác, ghi… Xem chi tiết | F6: Chưa thực hiện
A7: TC-RS-FUNC-001 / unit | B7: Thiết lập điểm đỏ（赤点設定） Hàng Thiết lập điểm đỏ（赤点設定） xuất hiện trong Thiết lập ô nhập（入力欄設定） cho mục… Xem chi tiết | C7: Chuẩn bị: Đang chuẩn bị Kỳ vọng: Đề xuất Dữ liệu (trích): Mục đơn vị Thao tác (trích): 1. Mở Thiết lập nhập điểm（成績入力設定）→ Thiết lập ô nhập（入力欄設定） của kỳ 1学期期末 (cuối kỳ học kỳ 1).… Xem chi tiết | D7: Kỳ vọng: Đề xuất 1. Theo Figma MW, hàng Thiết lập điểm đỏ（赤点設定） được đặt giữa hàng Tính tự động（自動計算） và hàng Thiết lập ẩn mục nhập（入力項目の非表示設定）. Đây là oracle UI PROPOSED; nếu bố cục khác, ghi… Xem chi tiết | F7: Chưa thực hiện
A8: TC-RS-FUNC-002 / choice | B8: Thiết lập điểm đỏ（赤点設定） Mục kiểu lựa chọn và Đạt/không đạt（合否） không có thao tác tạo quy tắc đỏ có hiệu… Xem chi tiết | C8: Chuẩn bị: Bị chặn Kỳ vọng: Đã xác nhận Dữ liệu (trích): Mục lựa chọn, gồm thử URL trực tiếp ở bước 3 Thao tác (trích): 1. Mở Thiết lập ô nhập（入力欄設定）.… Xem chi tiết | D8: Kỳ vọng: Đã xác nhận 1. Không có thao tác tạo quy tắc đỏ có hiệu lực cho hai mục này.… Xem chi tiết | F8: Chưa thực hiện
A9: TC-RS-FUNC-002 / passfail | B9: Thiết lập điểm đỏ（赤点設定） Mục kiểu lựa chọn và Đạt/không đạt（合否） không có thao tác tạo quy tắc đỏ có hiệu… Xem chi tiết | C9: Chuẩn bị: Bị chặn Kỳ vọng: Đã xác nhận Dữ liệu (trích): Mục Đạt/không đạt ở bước 1–2 Thao tác (trích): 1. Mở Thiết lập ô nhập（入力欄設定）.… Xem chi tiết | D9: Kỳ vọng: Đã xác nhận 1. Không có thao tác tạo quy tắc đỏ có hiệu lực cho hai mục này.… Xem chi tiết | F9: Chưa thực hiện
A10: TC-RS-FUNC-004 / Base | B10: Thiết lập điểm đỏ（赤点設定） Thêm quy tắc qua Điều kiện áp dụng（適用条件） và Ngưỡng（基準設定） rồi quay lại danh sách Xem chi tiết | C10: Chuẩn bị: Đang chuẩn bị Kỳ vọng: Đã xác nhận Dữ liệu (trích): Toàn bộ thủ tục theo đúng thứ tự; các đối chứng cùng fixture… Thao tác (trích): 1. Ở danh sách, bấm Thêm thiết lập chi tiết（詳細設定の追加）.… Xem chi tiết | D10: Kỳ vọng: Đã xác nhận 1. Sau mỗi lần cập nhật, màn quay về danh sách.… Xem chi tiết | F10: Chưa thực hiện
A11: TC-RS-FUNC-005 / Base | B11: Thiết lập điểm đỏ（赤点設定） Nhiều quy tắc hiển thị theo ưu tiên; đổi thứ tự bằng ▲▼ được lưu Xem chi tiết | C11: Chuẩn bị: Đang chuẩn bị Kỳ vọng: Đã xác nhận Dữ liệu (trích): Toàn bộ thủ tục theo đúng thứ tự; các đối chứng cùng fixture… Thao tác (trích): 1. Bấm ▼ ở quy tắc 1.… Xem chi tiết | D11: Kỳ vọng: Đã xác nhận 1. Sau bước 1 thứ tự là quy tắc 2, quy tắc 1, quy tắc 3 và giữ nguyên sau khi tải lại.… Xem chi tiết | F11: Chưa thực hiện
A12: TC-RS-FUNC-006 / cancel | B12: Thiết lập điểm đỏ（赤点設定） Xóa một quy tắc có xác nhận; Hủy（キャンセル） giữ nguyên Xem chi tiết | C12: Chuẩn bị: Đang chuẩn bị Kỳ vọng: Đã xác nhận Dữ liệu (trích): Hủy xóa Thao tác (trích): 1. Bấm Xóa（削除） ở quy tắc thứ 2, chọn Hủy（キャンセル）.… Xem chi tiết | D12: Kỳ vọng: Đã xác nhận 1. Hộp xác nhận nêu thiết lập sẽ bị xóa và kết quả học sinh chỉ cập nhật ở lần xét tiếp theo.… Xem chi tiết | F12: Chưa thực hiện
A13: TC-RS-FUNC-006 / delete | B13: Thiết lập điểm đỏ（赤点設定） Xóa một quy tắc có xác nhận; Hủy（キャンセル） giữ nguyên Xem chi tiết | C13: Chuẩn bị: Đang chuẩn bị Kỳ vọng: Đã xác nhận Dữ liệu (trích): Xác nhận xóa, dựng lại baseline trước lượt này Thao tác (trích): 1. Bấm Xóa（削除） ở quy tắc thứ 2, chọn Hủy（キャンセル）.… Xem chi tiết | D13: Kỳ vọng: Đã xác nhận 1. Hộp xác nhận nêu thiết lập sẽ bị xóa và kết quả học sinh chỉ cập nhật ở lần xét tiếp theo.… Xem chi tiết | F13: Chưa thực hiện
A14: TC-RS-FUNC-007 / back-threshold | B14: Thiết lập điểm đỏ（赤点設定） Quay lại（戻る）/hủy chỉnh sửa không lưu dữ liệu đang nhập Xem chi tiết | C14: Chuẩn bị: Đang chuẩn bị Kỳ vọng: Đã xác nhận Dữ liệu (trích): Quay lại từ màn ngưỡng Thao tác (trích): 1. Mở Ngưỡng của quy tắc “Cố định 30” (dưới 30), đổi 30 thành 35 và đổi sang Nhỏ hơn hoặc bằng（以下）.… Xem chi tiết | D14: Danh sách và hai màn vẫn hiện giá trị đã lưu trước đó (30, Nhỏ hơn, tên cũ). Bảo toàn: Giữ điểm, cấu hình và đối tượng không đích theo expected; chỉ thay phần thủ tục yêu cầu, không tự đổi oracle hoặc mở rộng phạm vi. | F14: Chưa thực hiện
A15: TC-RS-FUNC-007 / back-condition | B15: Thiết lập điểm đỏ（赤点設定） Quay lại（戻る）/hủy chỉnh sửa không lưu dữ liệu đang nhập Xem chi tiết | C15: Chuẩn bị: Đang chuẩn bị Kỳ vọng: Đã xác nhận Dữ liệu (trích): Quay lại từ màn điều kiện Thao tác (trích): 1. Mở Ngưỡng của quy tắc “Cố định 30” (dưới 30), đổi 30 thành 35 và đổi sang Nhỏ hơn hoặc bằng（以下）.… Xem chi tiết | D15: Danh sách và hai màn vẫn hiện giá trị đã lưu trước đó (30, Nhỏ hơn, tên cũ). Bảo toàn: Giữ điểm, cấu hình và đối tượng không đích theo expected; chỉ thay phần thủ tục yêu cầu, không tự đổi oracle hoặc mở rộng phạm vi. | F15: Chưa thực hiện
A16: TC-RS-FUNC-014 / incomplete-excluded | B16: Thiết lập điểm đỏ（赤点設定） Quy tắc mới chỉ có điều kiện, chưa có ngưỡng, không tham gia xét Xem chi tiết | C16: Chuẩn bị: Bị chặn Kỳ vọng: Đã xác nhận Dữ liệu (trích): Nhánh incomplete-excluded trong thủ tục và Expected của case;… Thao tác (trích): 1. Với `incomplete-excluded`, dựng fixture riêng, xem dòng chưa hoàn chỉnh; đăng ký S01=29 và đọc kết quả,… Xem chi tiết | D16: Kỳ vọng: Đã xác nhận 1. `incomplete-excluded`: dòng nhập dở hiện chưa thiết lập và cho mở ngưỡng; không tạo ngưỡng 0 ngầm. Bộ xét chọn đúng rule đối chứng T=30, S01=29 Đỏ; rule nhập dở không tham gia… Xem chi tiết | F16: Chưa thực hiện
... A573: TC-RS-REG-012 / sync | B573: Hồi quy AutoRating và các luồng hiện có — Hồi quy luồng hiện có Các luồng chuyển cấu hình không làm mất legacy | C573: Chuẩn bị: Đang chuẩn bị Kỳ vọng: Đã xác nhận Dữ liệu (trích): Đường sync DATA-019 Thao tác (trích): 1. Chuyển cấu hình qua copy/năm mới/import hoặc sync.… Xem chi tiết | D573: Legacy ở nguồn vẫn nguyên vẹn; đích không nhận kết quả cá nhân ngoài mapping hợp lệ và không dùng lại kết quả nguồn. Bảo toàn: Giữ điểm, cấu hình và đối tượng không đích theo expected; chỉ thay phần thủ tục yêu cầu, không tự đổi oracle hoặc mở rộng phạm vi. | F573: Chưa thực hiện

Sheet Chi tiết
A1: Chi tiết
A2: Từ ngữ trong nội dung nguồn: fixture = dữ liệu kiểm thử; seam = đường thực hiện/quan sát; oracle = căn cứ xác định kết quả; actual = kết quả thực tế.
A4: Mã kiểm thử | B4: Nội dung | C4: Chi tiết
A5: =HYPERLINK("#'Kiểm thử'!A"&(MATCH("TC-RS-FUNC-001 / integer",'Kiểm thử'!$A$5:$A$573,0)+4),"TC-RS-FUNC-001 / integer") | B5: Màn hình / chức năng | C5: Quản lý danh sách quy tắc đỏ của một mục — Thiết lập điểm đỏ（赤点設定） Hàng Thiết lập điểm đỏ（赤点設定） xuất hiện trong Thiết lập ô nhập（入力欄設定） cho mục điểm số
A6: =HYPERLINK("#'Kiểm thử'!A"&(MATCH("TC-RS-FUNC-001 / integer",'Kiểm thử'!$A$5:$A$573,0)+4),"TC-RS-FUNC-001 / integer") | B6: Điều kiện / thao tác | C6: Cấu hình: Đăng nhập tài khoản giáo viên có quyền sửa mục. Chưa có quy tắc đỏ cho mục số nguyên (M=100); mục số thập phân (M=100) có ít nhất một quy tắc. Kích hoạt: Thực hiện đúng thao tác và biến thể dưới đây; chỉ xem/xuất không tự chạy xét. Vị trí quan sát: Quan sát nơi nêu trong thủ tục/expected; dùng trích xuất không lọc để thấy cả ô đối chứng. Trạng thái không có dấu đỏ cần đọc thêm trạng thái lưu; output Excel/PDF dùng file thật. Vai trò / quyền: Dùng actor/quyền được nêu trong điều kiện; cấu hình bởi người được sửa đúng mục, ghi điểm bởi người phụ trách lớp, batch bởi người có quyền chạy; đầu ra và tài khoản học sinh giữ quyền riêng. Dữ liệu: môi trường test (trường A, năm học 2026), tài khoản giáo viên có quyền sửa mục, mục số nguyên (M=100), mục số thập phân (M=100), mục điểm đơn vị (đơn vị U1 có M riêng 40) Mục số nguyên Thao tác: 1. Mở Thiết lập nhập điểm（成績入力設定）→ Thiết lập ô nhập（入力欄設定） của kỳ 1学期期末 (cuối kỳ học kỳ 1). 2. Tìm hàng Thiết lập điểm đỏ（赤点設定） ở bảng mục nhập. 3. Bấm link của hàng này ở cột mục số nguyên (M=100), mục số thập phân (M=100), mục điểm đơn vị (đơn vị U1 có M riêng 40).
A7: =HYPERLINK("#'Kiểm thử'!A"&(MATCH("TC-RS-FUNC-001 / integer",'Kiểm thử'!$A$5:$A$573,0)+4),"TC-RS-FUNC-001 / integer") | B7: Điều kiện / thao tác | C7: Khôi phục: Trước mỗi biến thể, dựng lại điều kiện/dữ liệu đầu của case bằng đường được phép; giữ các reset/fixture độc lập đã nêu trong thủ tục. Bằng chứng: Ghi actual và URL bằng chứng/lỗi của đúng case/variant trong cùng report; giữ file Excel/PDF, ảnh trạng thái hoặc request/đọc dữ liệu khi case yêu cầu. Chưa có bằng chứng không được kết luận đã chạy. Kỳ vọng: Đề xuất Chuẩn bị: Đang chuẩn bị Chỉ là quan sát; kỳ vọng hoặc điều kiện kiểm chưa được xác nhận. Khoảng trống: Chưa có xác minh fixture, đường thực hiện và phép quan sát trên build của từng case chưa đánh giá. Giữ Draft; chỉ chuyển Ready khi chuẩn bị và seam của đúng case đã được xác minh.
A8: =HYPERLINK("#'Kiểm thử'!A"&(MATCH("TC-RS-FUNC-001 / integer",'Kiểm thử'!$A$5:$A$573,0)+4),"TC-RS-FUNC-001 / integer") | B8: Kết quả mong đợi | C8: 1. Theo Figma MW, hàng Thiết lập điểm đỏ（赤点設定） được đặt giữa hàng Tính tự động（自動計算） và hàng Thiết lập ẩn mục nhập（入力項目の非表示設定）. Đây là oracle UI PROPOSED; nếu bố cục khác, ghi Notes để đối chiếu, không mở bug từ riêng vị trí. 2. Có thao tác mở thiết lập cho mục số nguyên, số thập phân và điểm đơn vị. 3. Bấm link chuyển sang màn danh sách Thiết lập điểm đỏ（赤点設定） của đúng mục. Bảo toàn: Giữ điểm, cấu hình và đối tượng không đích theo expected; chỉ thay phần thủ tục yêu cầu, không tự đổi oracle hoặc mở rộng phạm vi.
A9: =HYPERLINK("#'Kiểm thử'!A"&(MATCH("TC-RS-FUNC-001 / decimal",'Kiểm thử'!$A$5:$A$573,0)+4),"TC-RS-FUNC-001 / decimal") | B9: Màn hình / chức năng | C9: Quản lý danh sách quy tắc đỏ của một mục — Thiết lập điểm đỏ（赤点設定） Hàng Thiết lập điểm đỏ（赤点設定） xuất hiện trong Thiết lập ô nhập（入力欄設定） cho mục điểm số
A10: =HYPERLINK("#'Kiểm thử'!A"&(MATCH("TC-RS-FUNC-001 / decimal",'Kiểm thử'!$A$5:$A$573,0)+4),"TC-RS-FUNC-001 / decimal") | B10: Điều kiện / thao tác | C10: Cấu hình: Đăng nhập tài khoản giáo viên có quyền sửa mục. Chưa có quy tắc đỏ cho mục số nguyên (M=100); mục số thập phân (M=100) có ít nhất một quy tắc. Kích hoạt: Thực hiện đúng thao tác và biến thể dưới đây; chỉ xem/xuất không tự chạy xét. Vị trí quan sát: Quan sát nơi nêu trong thủ tục/expected; dùng trích xuất không lọc để thấy cả ô đối chứng. Trạng thái không có dấu đỏ cần đọc thêm trạng thái lưu; output Excel/PDF dùng file thật. Vai trò / quyền: Dùng actor/quyền được nêu trong điều kiện; cấu hình bởi người được sửa đúng mục, ghi điểm bởi người phụ trách lớp, batch bởi người có quyền chạy; đầu ra và tài khoản học sinh giữ quyền riêng. Dữ liệu: môi trường test (trường A, năm học 2026), tài khoản giáo viên có quyền sửa mục, mục số nguyên (M=100), mục số thập phân (M=100), mục điểm đơn vị (đơn vị U1 có M riêng 40) Mục thập phân Thao tác: 1. Mở Thiết lập nhập điểm（成績入力設定）→ Thiết lập ô nhập（入力欄設定） của kỳ 1学期期末 (cuối kỳ học kỳ 1). 2. Tìm hàng Thiết lập điểm đỏ（赤点設定） ở bảng mục nhập. 3. Bấm link của hàng này ở cột mục số nguyên (M=100), mục số thập phân (M=100), mục điểm đơn vị (đơn vị U1 có M riêng 40).
A11: =HYPERLINK("#'Kiểm thử'!A"&(MATCH("TC-RS-FUNC-001 / decimal",'Kiểm thử'!$A$5:$A$573,0)+4),"TC-RS-FUNC-001 / decimal") | B11: Điều kiện / thao tác | C11: Khôi phục: Trước mỗi biến thể, dựng lại điều kiện/dữ liệu đầu của case bằng đường được phép; giữ các reset/fixture độc lập đã nêu trong thủ tục. Bằng chứng: Ghi actual và URL bằng chứng/lỗi của đúng case/variant trong cùng report; giữ file Excel/PDF, ảnh trạng thái hoặc request/đọc dữ liệu khi case yêu cầu. Chưa có bằng chứng không được kết luận đã chạy. Kỳ vọng: Đề xuất Chuẩn bị: Đang chuẩn bị Chỉ là quan sát; kỳ vọng hoặc điều kiện kiểm chưa được xác nhận. Khoảng trống: Chưa có xác minh fixture, đường thực hiện và phép quan sát trên build của từng case chưa đánh giá. Giữ Draft; chỉ chuyển Ready khi chuẩn bị và seam của đúng case đã được xác minh.
A12: =HYPERLINK("#'Kiểm thử'!A"&(MATCH("TC-RS-FUNC-001 / decimal",'Kiểm thử'!$A$5:$A$573,0)+4),"TC-RS-FUNC-001 / decimal") | B12: Kết quả mong đợi | C12: 1. Theo Figma MW, hàng Thiết lập điểm đỏ（赤点設定） được đặt giữa hàng Tính tự động（自動計算） và hàng Thiết lập ẩn mục nhập（入力項目の非表示設定）. Đây là oracle UI PROPOSED; nếu bố cục khác, ghi Notes để đối chiếu, không mở bug từ riêng vị trí. 2. Có thao tác mở thiết lập cho mục số nguyên, số thập phân và điểm đơn vị. 3. Bấm link chuyển sang màn danh sách Thiết lập điểm đỏ（赤点設定） của đúng mục. Bảo toàn: Giữ điểm, cấu hình và đối tượng không đích theo expected; chỉ thay phần thủ tục yêu cầu, không tự đổi oracle hoặc mở rộng phạm vi.
A13: =HYPERLINK("#'Kiểm thử'!A"&(MATCH("TC-RS-FUNC-001 / unit",'Kiểm thử'!$A$5:$A$573,0)+4),"TC-RS-FUNC-001 / unit") | B13: Màn hình / chức năng | C13: Quản lý danh sách quy tắc đỏ của một mục — Thiết lập điểm đỏ（赤点設定） Hàng Thiết lập điểm đỏ（赤点設定） xuất hiện trong Thiết lập ô nhập（入力欄設定） cho mục điểm số
A14: =HYPERLINK("#'Kiểm thử'!A"&(MATCH("TC-RS-FUNC-001 / unit",'Kiểm thử'!$A$5:$A$573,0)+4),"TC-RS-FUNC-001 / unit") | B14: Điều kiện / thao tác | C14: Cấu hình: Đăng nhập tài khoản giáo viên có quyền sửa mục. Chưa có quy tắc đỏ cho mục số nguyên (M=100); mục số thập phân (M=100) có ít nhất một quy tắc. Kích hoạt: Thực hiện đúng thao tác và biến thể dưới đây; chỉ xem/xuất không tự chạy xét. Vị trí quan sát: Quan sát nơi nêu trong thủ tục/expected; dùng trích xuất không lọc để thấy cả ô đối chứng. Trạng thái không có dấu đỏ cần đọc thêm trạng thái lưu; output Excel/PDF dùng file thật. Vai trò / quyền: Dùng actor/quyền được nêu trong điều kiện; cấu hình bởi người được sửa đúng mục, ghi điểm bởi người phụ trách lớp, batch bởi người có quyền chạy; đầu ra và tài khoản học sinh giữ quyền riêng. Dữ liệu: môi trường test (trường A, năm học 2026), tài khoản giáo viên có quyền sửa mục, mục số nguyên (M=100), mục số thập phân (M=100), mục điểm đơn vị (đơn vị U1 có M riêng 40) Mục đơn vị Thao tác: 1. Mở Thiết lập nhập điểm（成績入力設定）→ Thiết lập ô nhập（入力欄設定） của kỳ 1学期期末 (cuối kỳ học kỳ 1). 2. Tìm hàng Thiết lập điểm đỏ（赤点設定） ở bảng mục nhập. 3. Bấm link của hàng này ở cột mục số nguyên (M=100), mục số thập phân (M=100), mục điểm đơn vị (đơn vị U1 có M riêng 40).
A15: =HYPERLINK("#'Kiểm thử'!A"&(MATCH("TC-RS-FUNC-001 / unit",'Kiểm thử'!$A$5:$A$573,0)+4),"TC-RS-FUNC-001 / unit") | B15: Điều kiện / thao tác | C15: Khôi phục: Trước mỗi biến thể, dựng lại điều kiện/dữ liệu đầu của case bằng đường được phép; giữ các reset/fixture độc lập đã nêu trong thủ tục. Bằng chứng: Ghi actual và URL bằng chứng/lỗi của đúng case/variant trong cùng report; giữ file Excel/PDF, ảnh trạng thái hoặc request/đọc dữ liệu khi case yêu cầu. Chưa có bằng chứng không được kết luận đã chạy. Kỳ vọng: Đề xuất Chuẩn bị: Đang chuẩn bị Chỉ là quan sát; kỳ vọng hoặc điều kiện kiểm chưa được xác nhận. Khoảng trống: Chưa có xác minh fixture, đường thực hiện và phép quan sát trên build của từng case chưa đánh giá. Giữ Draft; chỉ chuyển Ready khi chuẩn bị và seam của đúng case đã được xác minh.
A16: =HYPERLINK("#'Kiểm thử'!A"&(MATCH("TC-RS-FUNC-001 / unit",'Kiểm thử'!$A$5:$A$573,0)+4),"TC-RS-FUNC-001 / unit") | B16: Kết quả mong đợi | C16: 1. Theo Figma MW, hàng Thiết lập điểm đỏ（赤点設定） được đặt giữa hàng Tính tự động（自動計算） và hàng Thiết lập ẩn mục nhập（入力項目の非表示設定）. Đây là oracle UI PROPOSED; nếu bố cục khác, ghi Notes để đối chiếu, không mở bug từ riêng vị trí. 2. Có thao tác mở thiết lập cho mục số nguyên, số thập phân và điểm đơn vị. 3. Bấm link chuyển sang màn danh sách Thiết lập điểm đỏ（赤点設定） của đúng mục. Bảo toàn: Giữ điểm, cấu hình và đối tượng không đích theo expected; chỉ thay phần thủ tục yêu cầu, không tự đổi oracle hoặc mở rộng phạm vi.
A17: =HYPERLINK("#'Kiểm thử'!A"&(MATCH("TC-RS-FUNC-002 / choice",'Kiểm thử'!$A$5:$A$573,0)+4),"TC-RS-FUNC-002 / choice") | B17: Màn hình / chức năng | C17: Quản lý danh sách quy tắc đỏ của một mục — Thiết lập điểm đỏ（赤点設定） Mục kiểu lựa chọn và Đạt/không đạt（合否） không có thao tác tạo quy tắc đỏ có hiệu lực
A18: =HYPERLINK("#'Kiểm thử'!A"&(MATCH("TC-RS-FUNC-002 / choice",'Kiểm thử'!$A$5:$A$573,0)+4),"TC-RS-FUNC-002 / choice") | B18: Điều kiện / thao tác | C18: Cấu hình: Đăng nhập tài khoản giáo viên có quyền sửa mục. Kích hoạt: Thực hiện đúng thao tác và biến thể dưới đây; chỉ xem/xuất không tự chạy xét. Vị trí quan sát: Quan sát nơi nêu trong thủ tục/expected; dùng trích xuất không lọc để thấy cả ô đối chứng. Trạng thái không có dấu đỏ cần đọc thêm trạng thái lưu; output Excel/PDF dùng file thật. Vai trò / quyền: Dùng actor/quyền được nêu trong điều kiện; cấu hình bởi người được sửa đúng mục, ghi điểm bởi người phụ trách lớp, batch bởi người có quyền chạy; đầu ra và tài khoản học sinh giữ quyền riêng. Dữ liệu: mục kiểu lựa chọn A/B/C, mục Đạt/không đạt（合否） Mục lựa chọn, gồm thử URL trực tiếp ở bước 3 Thao tác: 1. Mở Thiết lập ô nhập（入力欄設定）. 2. Xem hàng Thiết lập điểm đỏ（赤点設定） ở cột mục kiểu lựa chọn A/B/C, mục Đạt/không đạt（合否）. 3. Thử mở URL màn danh sách điểm đỏ của mục kiểu lựa chọn A/B/C bằng ID mục (nếu biết URL). Khôi phục: Trước mỗi biến thể, dựng lại điều kiện/dữ liệu đầu của case bằng đường được phép; giữ các reset/fixture độc lập đã nêu trong thủ tục. Bằng chứng: Ghi actual và URL bằng chứng/lỗi của đúng case/variant trong cùng report; giữ file
A19: =HYPERLINK("#'Kiểm thử'!A"&(MATCH("TC-RS-FUNC-002 / choice",'Kiểm thử'!$A$5:$A$573,0)+4),"TC-RS-FUNC-002 / choice") | B19: Điều kiện / thao tác | C19: Excel/PDF, ảnh trạng thái hoặc request/đọc dữ liệu khi case yêu cầu. Chưa có bằng chứng không được kết luận đã chạy. Kỳ vọng: Đã xác nhận Chuẩn bị: Bị chặn Chỉ là quan sát; kỳ vọng hoặc điều kiện kiểm chưa được xác nhận. Khoảng trống: BLOCKED — cần route/build URL hiện hành để kiểm trực tiếp endpoint; không coi việc chưa biết URL là READY. TC-RS-FUNC-002: hoàn thiện đúng fixture/seam; giữ expected và chưa kết luận thực thi.
A20: =HYPERLINK("#'Kiểm thử'!A"&(MATCH("TC-RS-FUNC-002 / choice",'Kiểm thử'!$A$5:$A$573,0)+4),"TC-RS-FUNC-002 / choice") | B20: Kết quả mong đợi | C20: 1. Không có thao tác tạo quy tắc đỏ có hiệu lực cho hai mục này. 2. Nếu có endpoint truy cập trực tiếp, server vẫn từ chối tạo/lưu quy tắc cho mục không thuộc loại số; không dùng việc URL không hiển thị làm bằng chứng duy nhất. Bảo toàn: Giữ điểm, cấu hình và đối tượng không đích theo expected; chỉ thay phần thủ tục yêu cầu, không tự đổi oracle hoặc mở rộng phạm vi.
A21: =HYPERLINK("#'Kiểm thử'!A"&(MATCH("TC-RS-FUNC-002 / passfail",'Kiểm thử'!$A$5:$A$573,0)+4),"TC-RS-FUNC-002 / passfail") | B21: Màn hình / chức năng | C21: Quản lý danh sách quy tắc đỏ của một mục — Thiết lập điểm đỏ（赤点設定） Mục kiểu lựa chọn và Đạt/không đạt（合否） không có thao tác tạo quy tắc đỏ có hiệu lực
A22: =HYPERLINK("#'Kiểm thử'!A"&(MATCH("TC-RS-FUNC-002 / passfail",'Kiểm thử'!$A$5:$A$573,0)+4),"TC-RS-FUNC-002 / passfail") | B22: Điều kiện / thao tác | C22: Cấu hình: Đăng nhập tài khoản giáo viên có quyền sửa mục. Kích hoạt: Thực hiện đúng thao tác và biến thể dưới đây; chỉ xem/xuất không tự chạy xét. Vị trí quan sát: Quan sát nơi nêu trong thủ tục/expected; dùng trích xuất không lọc để thấy cả ô đối chứng. Trạng thái không có dấu đỏ cần đọc thêm trạng thái lưu; output Excel/PDF dùng file thật. Vai trò / quyền: Dùng actor/quyền được nêu trong điều kiện; cấu hình bởi người được sửa đúng mục, ghi điểm bởi người phụ trách lớp, batch bởi người có quyền chạy; đầu ra và tài khoản học sinh giữ quyền riêng. Dữ liệu: mục kiểu lựa chọn A/B/C, mục Đạt/không đạt（合否） Mục Đạt/không đạt ở bước 1–2 Thao tác: 1. Mở Thiết lập ô nhập（入力欄設定）. 2. Xem hàng Thiết lập điểm đỏ（赤点設定） ở cột mục kiểu lựa chọn A/B/C, mục Đạt/không đạt（合否）. 3. Thử mở URL màn danh sách điểm đỏ của mục kiểu lựa chọn A/B/C bằng ID mục (nếu biết URL). Khôi phục: Trước mỗi biến thể, dựng lại điều kiện/dữ liệu đầu của case bằng đường được phép; giữ các reset/fixture độc lập đã nêu trong thủ tục. Bằng chứng: Ghi actual và URL bằng chứng/lỗi của đúng case/variant trong cùng report; giữ file
A23: =HYPERLINK("#'Kiểm thử'!A"&(MATCH("TC-RS-FUNC-002 / passfail",'Kiểm thử'!$A$5:$A$573,0)+4),"TC-RS-FUNC-002 / passfail") | B23: Điều kiện / thao tác | C23: Excel/PDF, ảnh trạng thái hoặc request/đọc dữ liệu khi case yêu cầu. Chưa có bằng chứng không được kết luận đã chạy. Kỳ vọng: Đã xác nhận Chuẩn bị: Bị chặn Chỉ là quan sát; kỳ vọng hoặc điều kiện kiểm chưa được xác nhận. Khoảng trống: BLOCKED — cần route/build URL hiện hành để kiểm trực tiếp endpoint; không coi việc chưa biết URL là READY. TC-RS-FUNC-002: hoàn thiện đúng fixture/seam; giữ expected và chưa kết luận thực thi.
A24: =HYPERLINK("#'Kiểm thử'!A"&(MATCH("TC-RS-FUNC-002 / passfail",'Kiểm thử'!$A$5:$A$573,0)+4),"TC-RS-FUNC-002 / passfail") | B24: Kết quả mong đợi | C24: 1. Không có thao tác tạo quy tắc đỏ có hiệu lực cho hai mục này. 2. Nếu có endpoint truy cập trực tiếp, server vẫn từ chối tạo/lưu quy tắc cho mục không thuộc loại số; không dùng việc URL không hiển thị làm bằng chứng duy nhất. Bảo toàn: Giữ điểm, cấu hình và đối tượng không đích theo expected; chỉ thay phần thủ tục yêu cầu, không tự đổi oracle hoặc mở rộng phạm vi.
A25: =HYPERLINK("#'Kiểm thử'!A"&(MATCH("TC-RS-FUNC-004 / Base",'Kiểm thử'!$A$5:$A$573,0)+4),"TC-RS-FUNC-004 / Base") | B25: Màn hình / chức năng | C25: Quản lý danh sách quy tắc đỏ của một mục — Thiết lập điểm đỏ（赤点設定） Thêm quy tắc qua Điều kiện áp dụng（適用条件） và Ngưỡng（基準設定） rồi quay lại danh sách
A26: =HYPERLINK("#'Kiểm thử'!A"&(MATCH("TC-RS-FUNC-004 / Base",'Kiểm thử'!$A$5:$A$573,0)+4),"TC-RS-FUNC-004 / Base") | B26: Điều kiện / thao tác | C26: Cấu hình: mục số nguyên (M=100) đã có cặp quy tắc cùng áp dụng (dưới 20 và dưới 30) (2 quy tắc). Đăng nhập tài khoản giáo viên có quyền sửa mục. Kích hoạt: Thực hiện đúng thao tác và biến thể dưới đây; chỉ xem/xuất không tự chạy xét. Vị trí quan sát: Quan sát nơi nêu trong thủ tục/expected; dùng trích xuất không lọc để thấy cả ô đối chứng. Trạng thái không có dấu đỏ cần đọc thêm trạng thái lưu; output Excel/PDF dùng file thật. Vai trò / quyền: Dùng actor/quyền được nêu trong điều kiện; cấu hình bởi người được sửa đúng mục, ghi điểm bởi người phụ trách lớp, batch bởi người có quyền chạy; đầu ra và tài khoản học sinh giữ quyền riêng. Dữ liệu: mục số nguyên (M=100), cặp quy tắc cùng áp dụng (dưới 20 và dưới 30); quy tắc “Cố định 30” (dưới 30) Toàn bộ thủ tục theo đúng thứ tự; các đối chứng cùng fixture được kiểm trong cùng lượt, không bỏ bước Thao tác: 1. Ở danh sách, bấm Thêm thiết lập chi tiết（詳細設定の追加）. 2. Nhập Tên thiết lập（設定名称） "Cố định 30", chọn Toàn bộ đối tượng（全員が対象）, bấm Cập nhật（更新する）. 3. Mở Ngưỡng, chọn Điểm cố định（固定点数）, nhập 30, chọn Nhỏ hơn（未満）, bấm Cập nhật（更新
A27: =HYPERLINK("#'Kiểm thử'!A"&(MATCH("TC-RS-FUNC-004 / Base",'Kiểm thử'!$A$5:$A$573,0)+4),"TC-RS-FUNC-004 / Base") | B27: Điều kiện / thao tác | C27: する）. 4. Xem danh sách. Khôi phục: Trước mỗi biến thể, dựng lại điều kiện/dữ liệu đầu của case bằng đường được phép; giữ các reset/fixture độc lập đã nêu trong thủ tục. Bằng chứng: Ghi actual và URL bằng chứng/lỗi của đúng case/variant trong cùng report; giữ file Excel/PDF, ảnh trạng thái hoặc request/đọc dữ liệu khi case yêu cầu. Chưa có bằng chứng không được kết luận đã chạy. Kỳ vọng: Đã xác nhận Chuẩn bị: Đang chuẩn bị Chỉ là quan sát; kỳ vọng hoặc điều kiện kiểm chưa được xác nhận. Khoảng trống: Chưa có xác minh fixture, đường thực hiện và phép quan sát trên build của từng case chưa đánh giá. Giữ Draft; chỉ chuyển Ready khi chuẩn bị và seam của đúng case đã được xác minh.
A28: =HYPERLINK("#'Kiểm thử'!A"&(MATCH("TC-RS-FUNC-004 / Base",'Kiểm thử'!$A$5:$A$573,0)+4),"TC-RS-FUNC-004 / Base") | B28: Kết quả mong đợi | C28: 1. Sau mỗi lần cập nhật, màn quay về danh sách. 2. Dòng mới hiện tên, tóm tắt điều kiện "toàn bộ" và ngưỡng "Điểm cố định: 30 điểm, Nhỏ hơn" đúng với dữ liệu đã lưu. 3. **PROPOSED (đặc tả v2 mục 4.4 “Lưu, đổi thứ tự và xóa”):** dòng mới nằm sau các quy tắc đã có. Bảo toàn: Giữ điểm, cấu hình và đối tượng không đích theo expected; chỉ thay phần thủ tục yêu cầu, không tự đổi oracle hoặc mở rộng phạm vi.
A29: =HYPERLINK("#'Kiểm thử'!A"&(MATCH("TC-RS-FUNC-005 / Base",'Kiểm thử'!$A$5:$A$573,0)+4),"TC-RS-FUNC-005 / Base") | B29: Màn hình / chức năng | C29: Quản lý danh sách quy tắc đỏ của một mục — Thiết lập điểm đỏ（赤点設定） Nhiều quy tắc hiển thị theo ưu tiên; đổi thứ tự bằng ▲▼ được lưu
A30: =HYPERLINK("#'Kiểm thử'!A"&(MATCH("TC-RS-FUNC-005 / Base",'Kiểm thử'!$A$5:$A$573,0)+4),"TC-RS-FUNC-005 / Base") | B30: Điều kiện / thao tác | C30: Cấu hình: mục số nguyên (M=100) có 3 quy tắc tên quy tắc 1, quy tắc 2, quy tắc 3 (tên tạm trong case) theo thứ tự. Kích hoạt: Thực hiện đúng thao tác và biến thể dưới đây; chỉ xem/xuất không tự chạy xét. Vị trí quan sát: Quan sát nơi nêu trong thủ tục/expected; dùng trích xuất không lọc để thấy cả ô đối chứng. Trạng thái không có dấu đỏ cần đọc thêm trạng thái lưu; output Excel/PDF dùng file thật. Vai trò / quyền: Dùng actor/quyền được nêu trong điều kiện; cấu hình bởi người được sửa đúng mục, ghi điểm bởi người phụ trách lớp, batch bởi người có quyền chạy; đầu ra và tài khoản học sinh giữ quyền riêng. Dữ liệu: mục số nguyên (M=100); quy tắc “Cố định 30” (dưới 30), cặp quy tắc cùng áp dụng (dưới 20 và dưới 30) Toàn bộ thủ tục theo đúng thứ tự; các đối chứng cùng fixture được kiểm trong cùng lượt, không bỏ bước Thao tác: 1. Bấm ▼ ở quy tắc 1. 2. Tải lại trang. 3. Bấm ▲ ở quy tắc 3. 4. Đăng xuất, đăng nhập lại, mở danh sách.
A31: =HYPERLINK("#'Kiểm thử'!A"&(MATCH("TC-RS-FUNC-005 / Base",'Kiểm thử'!$A$5:$A$573,0)+4),"TC-RS-FUNC-005 / Base") | B31: Điều kiện / thao tác | C31: Khôi phục: Trước mỗi biến thể, dựng lại điều kiện/dữ liệu đầu của case bằng đường được phép; giữ các reset/fixture độc lập đã nêu trong thủ tục. Bằng chứng: Ghi actual và URL bằng chứng/lỗi của đúng case/variant trong cùng report; giữ file Excel/PDF, ảnh trạng thái hoặc request/đọc dữ liệu khi case yêu cầu. Chưa có bằng chứng không được kết luận đã chạy. Kỳ vọng: Đã xác nhận Chuẩn bị: Đang chuẩn bị Chỉ là quan sát; kỳ vọng hoặc điều kiện kiểm chưa được xác nhận. Khoảng trống: Chưa có xác minh fixture, đường thực hiện và phép quan sát trên build của từng case chưa đánh giá. Giữ Draft; chỉ chuyển Ready khi chuẩn bị và seam của đúng case đã được xác minh.
A32: =HYPERLINK("#'Kiểm thử'!A"&(MATCH("TC-RS-FUNC-005 / Base",'Kiểm thử'!$A$5:$A$573,0)+4),"TC-RS-FUNC-005 / Base") | B32: Kết quả mong đợi | C32: 1. Sau bước 1 thứ tự là quy tắc 2, quy tắc 1, quy tắc 3 và giữ nguyên sau khi tải lại. 2. Sau bước 3 thứ tự là quy tắc 2, quy tắc 3, quy tắc 1 và giữ nguyên khi mở lại. 3. Đổi thứ tự không làm thay kết quả đỏ hiện có (kiểm ở case “Lưu cấu hình không xét; kết quả trước giữ tới lần chạy lại”). Bảo toàn: Giữ điểm, cấu hình và đối tượng không đích theo expected; chỉ thay phần thủ tục yêu cầu, không tự đổi oracle hoặc mở rộng phạm vi.
A33: =HYPERLINK("#'Kiểm thử'!A"&(MATCH("TC-RS-FUNC-006 / cancel",'Kiểm thử'!$A$5:$A$573,0)+4),"TC-RS-FUNC-006 / cancel") | B33: Màn hình / chức năng | C33: Quản lý danh sách quy tắc đỏ của một mục — Thiết lập điểm đỏ（赤点設定） Xóa một quy tắc có xác nhận; Hủy（キャンセル） giữ nguyên
A34: =HYPERLINK("#'Kiểm thử'!A"&(MATCH("TC-RS-FUNC-006 / cancel",'Kiểm thử'!$A$5:$A$573,0)+4),"TC-RS-FUNC-006 / cancel") | B34: Điều kiện / thao tác | C34: Cấu hình: mục số nguyên (M=100) có 2 quy tắc. Kích hoạt: Thực hiện đúng thao tác và biến thể dưới đây; chỉ xem/xuất không tự chạy xét. Vị trí quan sát: Quan sát nơi nêu trong thủ tục/expected; dùng trích xuất không lọc để thấy cả ô đối chứng. Trạng thái không có dấu đỏ cần đọc thêm trạng thái lưu; output Excel/PDF dùng file thật. Vai trò / quyền: Dùng actor/quyền được nêu trong điều kiện; cấu hình bởi người được sửa đúng mục, ghi điểm bởi người phụ trách lớp, batch bởi người có quyền chạy; đầu ra và tài khoản học sinh giữ quyền riêng. Dữ liệu: mục số nguyên (M=100); cặp quy tắc cùng áp dụng (dưới 20 và dưới 30) Hủy xóa Thao tác: 1. Bấm Xóa（削除） ở quy tắc thứ 2, chọn Hủy（キャンセル）. 2. Bấm Xóa（削除） lại, chọn Xóa（削除する）. Khôi phục: Trước mỗi biến thể, dựng lại điều kiện/dữ liệu đầu của case bằng đường được phép; giữ các reset/fixture độc lập đã nêu trong thủ tục. Bằng chứng: Ghi actual và URL bằng chứng/lỗi của đúng case/variant trong cùng report; giữ file Excel/PDF, ảnh trạng thái hoặc request/đọc dữ liệu khi case yêu cầu. Chưa có bằng chứng không được kết luận đã chạy.
A35: =HYPERLINK("#'Kiểm thử'!A"&(MATCH("TC-RS-FUNC-006 / cancel",'Kiểm thử'!$A$5:$A$573,0)+4),"TC-RS-FUNC-006 / cancel") | B35: Điều kiện / thao tác | C35: Kỳ vọng: Đã xác nhận Chuẩn bị: Đang chuẩn bị Chỉ là quan sát; kỳ vọng hoặc điều kiện kiểm chưa được xác nhận. Khoảng trống: Chưa có xác minh fixture, đường thực hiện và phép quan sát trên build của từng case chưa đánh giá. Giữ Draft; chỉ chuyển Ready khi chuẩn bị và seam của đúng case đã được xác minh.
A36: =HYPERLINK("#'Kiểm thử'!A"&(MATCH("TC-RS-FUNC-006 / cancel",'Kiểm thử'!$A$5:$A$573,0)+4),"TC-RS-FUNC-006 / cancel") | B36: Kết quả mong đợi | C36: 1. Hộp xác nhận nêu thiết lập sẽ bị xóa và kết quả học sinh chỉ cập nhật ở lần xét tiếp theo. 2. Hủy: danh sách giữ 2 quy tắc. 3. Xóa: danh sách còn 1 quy tắc; kết quả đỏ hiện có không đổi cho tới lần xét tiếp theo (case “Xóa quy tắc cuối: giữ kết quả tới lần chạy lại; chạy lại → Không áp dụng”). Bảo toàn: Giữ điểm, cấu hình và đối tượng không đích theo expected; chỉ thay phần thủ tục yêu cầu, không tự đổi oracle hoặc mở rộng phạm vi.
A37: =HYPERLINK("#'Kiểm thử'!A"&(MATCH("TC-RS-FUNC-006 / delete",'Kiểm thử'!$A$5:$A$573,0)+4),"TC-RS-FUNC-006 / delete") | B37: Màn hình / chức năng | C37: Quản lý danh sách quy tắc đỏ của một mục — Thiết lập điểm đỏ（赤点設定） Xóa một quy tắc có xác nhận; Hủy（キャンセル） giữ nguyên
A38: =HYPERLINK("#'Kiểm thử'!A"&(MATCH("TC-RS-FUNC-006 / delete",'Kiểm thử'!$A$5:$A$573,0)+4),"TC-RS-FUNC-006 / delete") | B38: Điều kiện / thao tác | C38: Cấu hình: mục số nguyên (M=100) có 2 quy tắc. Kích hoạt: Thực hiện đúng thao tác và biến thể dưới đây; chỉ xem/xuất không tự chạy xét. Vị trí quan sát: Quan sát nơi nêu trong thủ tục/expected; dùng trích xuất không lọc để thấy cả ô đối chứng. Trạng thái không có dấu đỏ cần đọc thêm trạng thái lưu; output Excel/PDF dùng file thật. Vai trò / quyền: Dùng actor/quyền được nêu trong điều kiện; cấu hình bởi người được sửa đúng mục, ghi điểm bởi người phụ trách lớp, batch bởi người có quyền chạy; đầu ra và tài khoản học sinh giữ quyền riêng. Dữ liệu: mục số nguyên (M=100); cặp quy tắc cùng áp dụng (dưới 20 và dưới 30) Xác nhận xóa, dựng lại baseline trước lượt này Thao tác: 1. Bấm Xóa（削除） ở quy tắc thứ 2, chọn Hủy（キャンセル）. 2. Bấm Xóa（削除） lại, chọn Xóa（削除する）. Khôi phục: Trước mỗi biến thể, dựng lại điều kiện/dữ liệu đầu của case bằng đường được phép; giữ các reset/fixture độc lập đã nêu trong thủ tục. Bằng chứng: Ghi actual và URL bằng chứng/lỗi của đúng case/variant trong cùng report; giữ file Excel/PDF, ảnh trạng thái hoặc request/đọc dữ liệu khi case yêu cầu. Chưa có bằng chứng không được kết luận đã chạy.
A39: =HYPERLINK("#'Kiểm thử'!A"&(MATCH("TC-RS-FUNC-006 / delete",'Kiểm thử'!$A$5:$A$573,0)+4),"TC-RS-FUNC-006 / delete") | B39: Điều kiện / thao tác | C39: Kỳ vọng: Đã xác nhận Chuẩn bị: Đang chuẩn bị Chỉ là quan sát; kỳ vọng hoặc điều kiện kiểm chưa được xác nhận. Khoảng trống: Chưa có xác minh fixture, đường thực hiện và phép quan sát trên build của từng case chưa đánh giá. Giữ Draft; chỉ chuyển Ready khi chuẩn bị và seam của đúng case đã được xác minh.
A40: =HYPERLINK("#'Kiểm thử'!A"&(MATCH("TC-RS-FUNC-006 / delete",'Kiểm thử'!$A$5:$A$573,0)+4),"TC-RS-FUNC-006 / delete") | B40: Kết quả mong đợi | C40: 1. Hộp xác nhận nêu thiết lập sẽ bị xóa và kết quả học sinh chỉ cập nhật ở lần xét tiếp theo. 2. Hủy: danh sách giữ 2 quy tắc. 3. Xóa: danh sách còn 1 quy tắc; kết quả đỏ hiện có không đổi cho tới lần xét tiếp theo (case “Xóa quy tắc cuối: giữ kết quả tới lần chạy lại; chạy lại → Không áp dụng”). Bảo toàn: Giữ điểm, cấu hình và đối tượng không đích theo expected; chỉ thay phần thủ tục yêu cầu, không tự đổi oracle hoặc mở rộng phạm vi.
A41: =HYPERLINK("#'Kiểm thử'!A"&(MATCH("TC-RS-FUNC-007 / back-threshold",'Kiểm thử'!$A$5:$A$573,0)+4),"TC-RS-FUNC-007 / back-threshold") | B41: Màn hình / chức năng | C41: Quản lý danh sách quy tắc đỏ của một mục — Thiết lập điểm đỏ（赤点設定） Quay lại（戻る）/hủy chỉnh sửa không lưu dữ liệu đang nhập
...
